Workbook

Sheet Maize Labor Rates
A1: Rate Sheet Maize
A6: 2025 PROJECT MAIZE RATE SHEET
A7: LABOR CLASSIFICATIONS AND MANAGEMENT SCHEDULED RATES | K7: included
A8: 1. Labor Classifications - Onsite | E8: Standard (1.0x) | H8: Overtime (1.5x) | I8: Doubletime (2.0x) | K8: Per Diem
A9: Project Engineer (daily reporting, RFI's, tracking installation, schedule) | E9: 140 | H9: =E9*1.5 -> 210 | I9: =E9*2 -> 280 | K9: 150
A10: General Superintendent | E10: 175 | H10: =E10*1.5 -> 262.5 | I10: =E10*2 -> 350
A11: Site Superintendent | E11: 175 | H11: =E11*1.5 -> 262.5 | I11: =E11*2 -> 350
A12: Foreman | E12: 162.5 | H12: =E12*1.5 -> 243.75 | I12: =E12*2 -> 325
A13: Electrician | E13: 150 | H13: =E13*1.5 -> 225 | I13: =E13*2 -> 300
A14: Apprentice | E14: 126.5 | H14: =E14*1.5 -> 189.75 | I14: =E14*2 -> 253
A15: Operator | E15: 102.31 | F15: 102.31 | G15: 102.31 | H15: =E15*1.5 -> 153.465 | I15: =E15*2 -> 204.62
A16: Steel Fabrication & Welding | B16: Steel Fabrication & Welding | C16: Steel Fabrication & Welding | D16: Steel Fabrication & Welding | E16: 150 | F16: 86.74 | G16: 86.74 | H16: =E16*1.5 -> 225 | I16: =E16*2 -> 300
A17: QA/QC Director | E17: 190 | H17: =E17*1.5 -> 285 | I17: =E17*2 -> 380
A18: QA/QC Manager | E18: 165 | H18: =E18*1.5 -> 247.5 | I18: =E18*2 -> 330
A19: QA/QC Agent | E19: 150 | H19: =E19*1.5 -> 225 | I19: =E19*2 -> 300
A20: Safety Agent | E20: 172.5 | H20: =E20*1.5 -> 258.75 | I20: =E20*2 -> 345
A21: Project Coordinator | E21: 135 | H21: =E21*1.5 -> 202.5 | I21: =E21*2 -> 270
A22: Site Resource Coordinator | E22: 135 | H22: =E22*1.5 -> 202.5 | I22: =E22*2 -> 270
A23: Administrative Coordinator (logistics, manpower) | E23: 125 | H23: =E23*1.5 -> 187.5 | I23: =E23*2 -> 250
A24: Project Accountanting (time entry, payroll) | E24: 135 | H24: =E24*1.5 -> 202.5 | I24: =E24*2 -> 270
A25: Billing Specialist (auditor, time, equipment, materials, billing) | E25: 140 | H25: =E25*1.5 -> 210 | I25: =E25*2 -> 280
A26: Project Executive | E26: 200 | H26: =E26*1.5 -> 300 | I26: =E26*2 -> 400
A27: Sr. Project Management | E27: 190 | H27: =E27*1.5 -> 285 | I27: =E27*2 -> 380
A28: Project Management | E28: 160 | H28: =E28*1.5 -> 240 | I28: =E28*2 -> 320
A35: 2. Labor Classifications Off-Site | E35: Standard (1.0x) | H35: Overtime (1.5x) | I35: Doubletime (2.0x) | K35: No Per Diem
A36: QA/QC Director | E36: 175 | H36: =E36*1.5 -> 262.5 | I36: =E36*2 -> 350
A37: Project Coordinator | E37: 120 | H37: =E37*1.5 -> 180 | I37: =E37*2 -> 240
A38: Administrative Coordinator (logistics, manpower) | E38: 110 | H38: =E38*1.5 -> 165 | I38: =E38*2 -> 220
A39: Project Accountanting (time entry, payroll) | E39: 120 | H39: =E39*1.5 -> 180 | I39: =E39*2 -> 240
A40: Billing Specialist (auditor, time, equipment, materials, billing) | E40: 90 | H40: =E40*1.5 -> 135 | I40: =E40*2 -> 180
A41: Project Executive | E41: 185 | H41: =E41*1.5 -> 277.5 | I41: =E41*2 -> 370
A42: Sr. Project Management | E42: 175 | H42: =E42*1.5 -> 262.5 | I42: =E42*2 -> 350
A43: Project Management | E43: 145 | H43: =E43*1.5 -> 217.5 | I43: =E43*2 -> 290
A44: Safety Director | E44: 135 | H44: =E44*1.5 -> 202.5 | I44: =E44*2 -> 270
A45: Electrical Engineer | E45: 150 | H45: =E45*1.5 -> 225 | I45: =E45*2 -> 300
A46: Electrical Designer (BIM, VDC, Pre-Construction) | E46: 125 | H46: =E46*1.5 -> 187.5 | I46: =E46*2 -> 250
A47: Estimator | E47: 125 | H47: =E47*1.5 -> 187.5 | I47: =E47*2 -> 250
E48: 0 | H48: =E48*1.5 -> 0 | I48: =E48*2 -> 0
E49: 0 | H49: =E49*1.5 -> 0 | I49: =E49*2 -> 0
E50: 0 | H50: =E50*1.5 -> 0 | I50: =E50*2 -> 0
...

Sheet INVOICE COVER
D1: INVOICE # 25108-39
D2: INVOICE DATE | E2: CUSTOMER NO. | F2: INVOICE NUMBER
A3: 10640 Deme Drive Suite M, Indianapolis IN 46236 | D3: 46190 | F3: 25108-39
A4: Customer Information | C4: Job Information | D4: P.O. NUMBER | E4: JOB. NO. | F4: PERIOD ENDING
A5: X-Wavetech LLC | C5: Marble NC | D5: 7277 | E5: 25108 | F5: 46180
A6: Christopher Remmers | C6: Austin Stoner | D6: Customer AP Contact | E6: InPwr Operations Contact | F6: InPwr Billing Contact
A7: 13994 Lake Price Drive | C7: 155 Palmer Lane | D7: Christopher Remmers | E7: Dave Hedge | F7: Kyah InskeeP
A8: Orlando, FL 32826 | C8: Marble, NC 28905 | D8: 201-314-2811 | E8: 317-417-9885 | F8: 317-723-3375
A9: 201-314-2811 | C9: 463-246-5321 | D9: chris@x-wavetech.com | E9: dhedge@inpwrinc.com | F9: AR@INPWRINC.COM
A10: *Please note, progress billing only and does not represent all applicable charges for this period; future invoicing may be applicable and billed upon substantial completion
A11: 6 | B11: DESCRIPTION | F11: Amount | K11: 1
A12: 1 | B12: Labor | F12: ='1ST Shift'!AG68 -> 2041.25
A13: 2 | B13: Equipment | F13: ='3rd Party Equipment'!F60+'IP Equip'!D38+'IP Equip_Tools'!S34 -> 0
A14: 3 | B14: Materials | F14: =Materials!F60 -> 0
A15: 4 | B15: Incurred Cost | F15: ='Incurred Costs'!F57 -> 0
A16: 5 | B16: SubContractors | F16: =Subcontractors!F60 -> 0
H17: =37+43 -> 80
B19: Extended ROM Total | F19: =F12+F13+F14+F15+F16+F17 -> 2041.25
I20: ='6001 1st'!AC168+'6002 2nd'!AC168+'6005 1ST'!AC182+'6006 2nd'!AC169+'6007 1st '!AC181+'6008 2nd'!AC181+#REF!+#REF! -> #REF!
G23: =D3+50 -> 46240
A47: Invoice Total Due 8/6/26 | F47: =F19 -> 2041.25

Sheet INVOICE COVER 7256
D1: INVOICE # 25108-09
D2: INVOICE DATE | E2: CUSTOMER NO. | F2: INVOICE NUMBER
A3: 10640 Deme Drive Suite M, Indianapolis IN 46236 | D3: 45951 | F3: 25108-09
A4: Customer Information | C4: Job Information | D4: P.O. NUMBER | E4: JOB. NO. | F4: PERIOD ENDING
A5: X-Wavetech LLC | C5: Marble NC | D5: 7256 | E5: 25108 | F5: 45942
A6: Christopher Remmers | C6: Austin Stoner | D6: Customer AP Contact | E6: InPwr Operations Contact | F6: InPwr Billing Contact
A7: 13994 Lake Price Drive | C7: 155 Palmer Lane | D7: Christopher Remmers | E7: Dave Hedge | F7: Kyah Inskeep/Mandy Vo
A8: Orlando, FL 32826 | C8: Marble, NC 28905 | D8: 201-314-2811 | E8: 317-417-9885 | F8: 317-723-3375
A9: 201-314-2811 | C9: 463-246-5321 | D9: chris@x-wavetech.com | E9: dhedge@inpwrinc.com | F9: AR@INPWRINC.COM
A10: *Please note, progress billing only and does not represent all applicable charges for this period; future invoicing may be applicable and billed upon substantial completion | K10: 12
A11: 6 | B11: DESCRIPTION | F11: Amount | K11: 1
A12: 1 | B12: Extended ROM TM Labor | F12: ='1ST Shift'!AG68+'2ND SHIFT'!AG294 -> #REF!
A13: 2 | B13: Equipment | F13: ='3rd Party Equipment'!F60+'IP Equip_Tools'!S34 -> 0
A14: 3 | B14: Materials | F14: =Materials!F60 -> 0
A15: 4 | B15: Incurred Cost | F15: ='Incurred Costs'!F57 -> 0
A16: 5 | B16: SubContractors | F16: =Subcontractors!F60 -> 0
A17: 6 | B17: Mobilization Charge - 12 Mobilized from 9.29.25 thru 10.12.25 | F17: 12000 | H17: =37+43 -> 80
B19: Extended ROM TM Total from 9.29.25 thru 10.12.25 | F19: =F12+F13+F14+F15+F16+F17 -> #REF!
I20: ='6001 1st'!AC168+'6002 2nd'!AC168+'6005 1ST'!AC182+'6006 2nd'!AC169+'6007 1st '!AC181+'6008 2nd'!AC181+#REF!+#REF! -> #REF!
B22: Total Left to Bill under PO #7256 - This Total Closes out PO #7256 | F22: 1700000
G23: =D3+50 -> 46001
A47: Invoice Total Due 12/10/25 | F47: =F22 -> 1700000

Sheet INVOICE COVER 7277
D1: INVOICE # 25108-10
D2: INVOICE DATE | E2: CUSTOMER NO. | F2: INVOICE NUMBER
A3: 10640 Deme Drive Suite M, Indianapolis IN 46236 | D3: 45951 | F3: 25108-10
A4: Customer Information | C4: Job Information | D4: P.O. NUMBER | E4: JOB. NO. | F4: PERIOD ENDING
A5: X-Wavetech LLC | C5: Marble NC | D5: 7277 | E5: 25108 | F5: 45942
A6: Christopher Remmers | C6: Austin Stoner | D6: Customer AP Contact | E6: InPwr Operations Contact | F6: InPwr Billing Contact
A7: 13994 Lake Price Drive | C7: 155 Palmer Lane | D7: Christopher Remmers | E7: Dave Hedge | F7: Kyah Inskeep/Mandy Vo
A8: Orlando, FL 32826 | C8: Marble, NC 28905 | D8: 201-314-2811 | E8: 317-417-9885 | F8: 317-723-3375
A9: 201-314-2811 | C9: 463-246-5321 | D9: chris@x-wavetech.com | E9: dhedge@inpwrinc.com | F9: AR@INPWRINC.COM
A10: *Please note, progress billing only and does not represent all applicable charges for this period; future invoicing may be applicable and billed upon substantial completion | K10: 12
A11: 6 | B11: DESCRIPTION | F11: Amount | K11: 1
A12: 1 | B12: Extended ROM TM Labor | F12: ='1ST Shift'!AG68+'2ND SHIFT'!AG294 -> #REF!
A13: 2 | B13: Equipment | F13: ='3rd Party Equipment'!F60+'IP Equip_Tools'!S34 -> 0
A14: 3 | B14: Materials | F14: =Materials!F60 -> 0
A15: 4 | B15: Incurred Cost | F15: ='Incurred Costs'!F57 -> 0
A16: 5 | B16: SubContractors | F16: =Subcontractors!F60 -> 0
A17: 6 | B17: Mobilization Charge - 12 Mobilized from 9.29.25 thru 10.12.25 | F17: 12000 | H17: =37+43 -> 80
B19: Extended ROM TM Total from 9.29.25 thru 10.12.25 | F19: =F12+F13+F14+F15+F16+F17 -> #REF!
I20: ='6001 1st'!AC168+'6002 2nd'!AC168+'6005 1ST'!AC182+'6006 2nd'!AC169+'6007 1st '!AC181+'6008 2nd'!AC181+#REF!+#REF! -> #REF!
B22: Subtotal to start billing under PO #7277. All other billing going forward will fall under this PO | F22: 1471448.8
B23: Inclusive of this total on invoice 25108-10 | G23: =D3+50 -> 46001
A47: Invoice Total Due 12/10/25 | F47: =F22 -> 1471448.8

Sheet 1ST Shift
A1: Extended ROM 1st Shift | AK1: On 11.21.25 Previously Billed | AL1: will hit 12.5.25 payroll | AM1: Should be on JCH
A2: INPWR INVOICE NUMBER | B2: ='INVOICE COVER'!F3 -> 25108-39
A3: CUSTOMER REFERENCE | B3: ='INVOICE COVER'!D5 -> 7277
A4: JOB NAME | B4: ='INVOICE COVER 7256'!C5 -> Marble NC
A5: JOB NUMBER | B5: ='INVOICE COVER 7256'!E5 -> 25108
A6: Preiod Ending | B6: ='INVOICE COVER'!F5 -> 46180
A7: EMPLOYEE NAME | B7: CLASS | C7: REGULAR | D7: Per Diem | E7: PER DAY | L7: =B6-6 -> 46174 | N7: =B6-5 -> 46175 | P7: =B6-4 -> 46176 | R7: =B6-3 -> 46177 | T7: =B6-2 -> 46178 | V7: =B6-1 -> 46179 | X7: =B6 -> 46180 | Z7: REG | AA7: OT | AB7: DT | AC7: Total | AD7: ST. LABOR | AE7: OT LABOR | AF7: DT LABOR | AG7: LABOR
C8: RATE | D8: Y/N | E8: =B6-6 -> 46174 | F8: =E8+1 -> 46175 | G8: =F8+1 -> 46176 | H8: =G8+1 -> 46177 | I8: =H8+1 -> 46178 | J8: =I8+1 -> 46179 | K8: =J8+1 -> 46180 | L8: REG. | M8: OT | N8: REG. | O8: OT | P8: REG | Q8: OT | R8: REG | S8: OT | T8: REG | U8: OT | V8: REG | W8: OT | X8: REG | Y8: OT | Z8: TOT | AA8: TOT | AB8: Hours | AC8: Hours | AD8: TOTAL | AE8: TOTAL | AF8: TOTAL | AG8: TOTAL
A10: ALEMAN, GABRIEL | B10: Electrician | C10: =VLOOKUP('1ST Shift'!$B10,Table6[],2,FALSE) -> 150 | L10: =(IF(E10>0,MIN(8,E10),"")) | M10: =IF((E10)>8,SUM(E10-L10),"") | N10: =(IF(F10>0,MIN(8,F10),"")) | O10: =IF((F10)>8,SUM(F10-N10),"") | P10: =(IF(G10>0,MIN(8,G10),"")) | Q10: =IF((G10)>8,SUM(G10-P10),"") | R10: =(IF(H10>0,MIN(8,H10),"")) | S10: =IF((H10)>8,SUM(H10-R10),"") | T10: =(IF(I10>0,MIN(8,I10),"")) | U10: =IF((I10)>8,SUM(I10-T10),"") | V10: =(IF(J10>0,MIN(8,J10),"")) | W10: =IF((J10)>8,SUM(J10-V10),"") | X10: =(IF(K10>0,MIN(8,K10),"")) | Y10: =IF((K10)>8,SUM(K10-X10),"") | Z10: =VLOOKUP(A10,Table4[#All],2,FALSE) -> 0 | AA10: =VLOOKUP(A10,Table4[#All],3,FALSE) -> 0 | AB10: =IFERROR(VLOOKUP(A10,Table13[[#Headers],[#Data]],7,FALSE),0) -> 0 | AC10: =SUM(Z10:AB10) -> 0 | AD10: =Z10*C10 -> 0 | AE10: =AA10*C10*1.5 -> 0 | AF10: =AB10*C10*2 -> 0 | AG10: =AD10+AE10+AF10 -> 0
A11: ARNOLD, CHARLES | B11: QA/QC | C11: =VLOOKUP('1ST Shift'!$B11,Table6[],2,FALSE) -> 165 | L11: =(IF(E11>0,MIN(8,E11),"")) | M11: =IF((E11)>8,SUM(E11-L11),"") | N11: =(IF(F11>0,MIN(8,F11),"")) | O11: =IF((F11)>8,SUM(F11-N11),"") | P11: =(IF(G11>0,MIN(8,G11),"")) | Q11: =IF((G11)>8,SUM(G11-P11),"") | R11: =(IF(H11>0,MIN(8,H11),"")) | S11: =IF((H11)>8,SUM(H11-R11),"") | T11: =(IF(I11>0,MIN(8,I11),"")) | U11: =IF((I11)>8,SUM(I11-T11),"") | V11: =(IF(J11>0,MIN(8,J11),"")) | W11: =IF((J11)>8,SUM(J11-V11),"") | X11: =(IF(K11>0,MIN(8,K11),"")) | Y11: =IF((K11)>8,SUM(K11-X11),"") | Z11: =VLOOKUP(A11,Table4[#All],2,FALSE) -> 0 | AA11: =VLOOKUP(A11,Table4[#All],3,FALSE) -> 0 | AB11: =IFERROR(VLOOKUP(A11,Table13[[#Headers],[#Data]],7,FALSE),0) -> 0 | AC11: =SUM(Z11:AB11) -> 0 | AD11: =Z11*C11 -> 0 | AE11: =AA11*C11*1.5 -> 0 | AF11: =AB11*C11*2 -> 0 | AG11: =AD11+AE11+AF11 -> 0
A12: BASTIDAS, OMARELYS QUERO | B12: Electrician | C12: =VLOOKUP('1ST Shift'!$B12,Table6[],2,FALSE) -> 150 | L12: =(IF(E12>0,MIN(8,E12),"")) | M12: =IF((E12)>8,SUM(E12-L12),"") | N12: =(IF(F12>0,MIN(8,F12),"")) | O12: =IF((F12)>8,SUM(F12-N12),"") | P12: =(IF(G12>0,MIN(8,G12),"")) | Q12: =IF((G12)>8,SUM(G12-P12),"") | R12: =(IF(H12>0,MIN(8,H12),"")) | S12: =IF((H12)>8,SUM(H12-R12),"") | T12: =(IF(I12>0,MIN(8,I12),"")) | U12: =IF((I12)>8,SUM(I12-T12),"") | V12: =(IF(J12>0,MIN(8,J12),"")) | W12: =IF((J12)>8,SUM(J12-V12),"") | X12: =(IF(K12>0,MIN(8,K12),"")) | Y12: =IF((K12)>8,SUM(K12-X12),"") | Z12: =VLOOKUP(A12,Table4[#All],2,FALSE) -> 0 | AA12: =VLOOKUP(A12,Table4[#All],3,FALSE) -> 0 | AB12: =IFERROR(VLOOKUP(A12,Table13[[#Headers],[#Data]],7,FALSE),0) -> 0 | AC12: =SUM(Z12:AB12) -> 0 | AD12: =Z12*C12 -> 0 | AE12: =AA12*C12*1.5 -> 0 | AF12: =AB12*C12*2 -> 0 | AG12: =AD12+AE12+AF12 -> 0
A13: BAUTISTA, MELVIN HERNANDEZ | B13: Electrician | C13: =VLOOKUP('1ST Shift'!$B13,Table6[],2,FALSE) -> 150 | L13: =(IF(E13>0,MIN(8,E13),"")) | M13: =IF((E13)>8,SUM(E13-L13),"") | N13: =(IF(F13>0,MIN(8,F13),"")) | O13: =IF((F13)>8,SUM(F13-N13),"") | P13: =(IF(G13>0,MIN(8,G13),"")) | Q13: =IF((G13)>8,SUM(G13-P13),"") | R13: =(IF(H13>0,MIN(8,H13),"")) | S13: =IF((H13)>8,SUM(H13-R13),"") | T13: =(IF(I13>0,MIN(8,I13),"")) | U13: =IF((I13)>8,SUM(I13-T13),"") | V13: =(IF(J13>0,MIN(8,J13),"")) | W13: =IF((J13)>8,SUM(J13-V13),"") | X13: =(IF(K13>0,MIN(8,K13),"")) | Y13: =IF((K13)>8,SUM(K13-X13),"") | Z13: =VLOOKUP(A13,Table4[#All],2,FALSE) -> 0 | AA13: =VLOOKUP(A13,Table4[#All],3,FALSE) -> 0 | AB13: =IFERROR(VLOOKUP(A13,Table13[[#Headers],[#Data]],7,FALSE),0) -> 0 | AC13: =SUM(Z13:AB13) -> 0 | AD13: =Z13*C13 -> 0 | AE13: =AA13*C13*1.5 -> 0 | AF13: =AB13*C13*2 -> 0 | AG13: =AD13+AE13+AF13 -> 0
A14: BEARER, BENJAMIN | B14: QA/QC | C14: =VLOOKUP('1ST Shift'!$B14,Table6[],2,FALSE) -> 165 | L14: =(IF(E14>0,MIN(8,E14),"")) | M14: =IF((E14)>8,SUM(E14-L14),"") | N14: =(IF(F14>0,MIN(8,F14),"")) | O14: =IF((F14)>8,SUM(F14-N14),"") | P14: =(IF(G14>0,MIN(8,G14),"")) | Q14: =IF((G14)>8,SUM(G14-P14),"") | R14: =(IF(H14>0,MIN(8,H14),"")) | S14: =IF((H14)>8,SUM(H14-R14),"") | T14: =(IF(I14>0,MIN(8,I14),"")) | U14: =IF((I14)>8,SUM(I14-T14),"") | V14: =(IF(J14>0,MIN(8,J14),"")) | W14: =IF((J14)>8,SUM(J14-V14),"") | X14: =(IF(K14>0,MIN(8,K14),"")) | Y14: =IF((K14)>8,SUM(K14-X14),"") | Z14: =VLOOKUP(A14,Table4[#All],2,FALSE) -> 0 | AA14: =VLOOKUP(A14,Table4[#All],3,FALSE) -> 0 | AB14: =IFERROR(VLOOKUP(A14,Table13[[#Headers],[#Data]],7,FALSE),0) -> 0 | AC14: =SUM(Z14:AB14) -> 0 | AD14: =Z14*C14 -> 0 | AE14: =AA14*C14*1.5 -> 0 | AF14: =AB14*C14*2 -> 0 | AG14: =AD14+AE14+AF14 -> 0 | AH14: biweekly | AL14: 24 | AM14: =AC14-AL14 -> -24
A15: BONILLA, DOMINGO | B15: Electrician | C15: =VLOOKUP('1ST Shift'!$B15,Table6[],2,FALSE) -> 150 | L15: =(IF(E15>0,MIN(8,E15),"")) | M15: =IF((E15)>8,SUM(E15-L15),"") | N15: =(IF(F15>0,MIN(8,F15),"")) | O15: =IF((F15)>8,SUM(F15-N15),"") | P15: =(IF(G15>0,MIN(8,G15),"")) | Q15: =IF((G15)>8,SUM(G15-P15),"") | R15: =(IF(H15>0,MIN(8,H15),"")) | S15: =IF((H15)>8,SUM(H15-R15),"") | T15: =(IF(I15>0,MIN(8,I15),"")) | U15: =IF((I15)>8,SUM(I15-T15),"") | V15: =(IF(J15>0,MIN(8,J15),"")) | W15: =IF((J15)>8,SUM(J15-V15),"") | X15: =(IF(K15>0,MIN(8,K15),"")) | Y15: =IF((K15)>8,SUM(K15-X15),"") | Z15: =VLOOKUP(A15,Table4[#All],2,FALSE) -> 0 | AA15: =VLOOKUP(A15,Table4[#All],3,FALSE) -> 0 | AB15: =IFERROR(VLOOKUP(A15,Table13[[#Headers],[#Data]],7,FALSE),0) -> 0 | AC15: =SUM(Z15:AB15) -> 0 | AD15: =Z15*C15 -> 0 | AE15: =AA15*C15*1.5 -> 0 | AF15: =AB15*C15*2 -> 0 | AG15: =AD15+AE15+AF15 -> 0
A16: BRAVO, JOSE BRICERNO | B16: Electrician | C16: =VLOOKUP('1ST Shift'!$B16,Table6[],2,FALSE) -> 150 | L16: =(IF(E16>0,MIN(8,E16),"")) | M16: =IF((E16)>8,SUM(E16-L16),"") | N16: =(IF(F16>0,MIN(8,F16),"")) | O16: =IF((F16)>8,SUM(F16-N16),"") | P16: =(IF(G16>0,MIN(8,G16),"")) | Q16: =IF((G16)>8,SUM(G16-P16),"") | R16: =(IF(H16>0,MIN(8,H16),"")) | S16: =IF((H16)>8,SUM(H16-R16),"") | T16: =(IF(I16>0,MIN(8,I16),"")) | U16: =IF((I16)>8,SUM(I16-T16),"") | V16: =(IF(J16>0,MIN(8,J16),"")) | W16: =IF((J16)>8,SUM(J16-V16),"") | X16: =(IF(K16>0,MIN(8,K16),"")) | Y16: =IF((K16)>8,SUM(K16-X16),"") | Z16: =VLOOKUP(A16,Table4[#All],2,FALSE) -> 0 | AA16: =VLOOKUP(A16,Table4[#All],3,FALSE) -> 0 | AB16: =IFERROR(VLOOKUP(A16,Table13[[#Headers],[#Data]],7,FALSE),0) -> 0 | AC16: =SUM(Z16:AB16) -> 0 | AD16: =Z16*C16 -> 0 | AE16: =AA16*C16*1.5 -> 0 | AF16: =AB16*C16*2 -> 0 | AG16: =AD16+AE16+AF16 -> 0
A17: BURGOS, FERNANDO | B17: QA/QC | C17: =VLOOKUP('1ST Shift'!$B17,Table6[],2,FALSE) -> 165 | L17: =(IF(E17>0,MIN(8,E17),"")) | M17: =IF((E17)>8,SUM(E17-L17),"") | N17: =(IF(F17>0,MIN(8,F17),"")) | O17: =IF((F17)>8,SUM(F17-N17),"") | P17: =(IF(G17>0,MIN(8,G17),"")) | Q17: =IF((G17)>8,SUM(G17-P17),"") | R17: =(IF(H17>0,MIN(8,H17),"")) | S17: =IF((H17)>8,SUM(H17-R17),"") | T17: =(IF(I17>0,MIN(8,I17),"")) | U17: =IF((I17)>8,SUM(I17-T17),"") | V17: =(IF(J17>0,MIN(8,J17),"")) | W17: =IF((J17)>8,SUM(J17-V17),"") | X17: =(IF(K17>0,MIN(8,K17),"")) | Y17: =IF((K17)>8,SUM(K17-X17),"") | Z17: =VLOOKUP(A17,Table4[#All],2,FALSE) -> 0 | AA17: =VLOOKUP(A17,Table4[#All],3,FALSE) -> 0 | AB17: =IFERROR(VLOOKUP(A17,Table13[[#Headers],[#Data]],7,FALSE),0) -> 0 | AC17: =SUM(Z17:AB17) -> 0 | AD17: =Z17*C17 -> 0 | AE17: =AA17*C17*1.5 -> 0 | AF17: =AB17*C17*2 -> 0 | AG17: =AD17+AE17+AF17 -> 0
A18: CARDOZO, ENRIQUE | B18: Electrician | C18: =VLOOKUP('1ST Shift'!$B18,Table6[],2,FALSE) -> 150 | L18: =(IF(E18>0,MIN(8,E18),"")) | M18: =IF((E18)>8,SUM(E18-L18),"") | N18: =(IF(F18>0,MIN(8,F18),"")) | O18: =IF((F18)>8,SUM(F18-N18),"") | P18: =(IF(G18>0,MIN(8,G18),"")) | Q18: =IF((G18)>8,SUM(G18-P18),"") | R18: =(IF(H18>0,MIN(8,H18),"")) | S18: =IF((H18)>8,SUM(H18-R18),"") | T18: =(IF(I18>0,MIN(8,I18),"")) | U18: =IF((I18)>8,SUM(I18-T18),"") | V18: =(IF(J18>0,MIN(8,J18),"")) | W18: =IF((J18)>8,SUM(J18-V18),"") | X18: =(IF(K18>0,MIN(8,K18),"")) | Y18: =IF((K18)>8,SUM(K18-X18),"") | Z18: =VLOOKUP(A18,Table4[#All],2,FALSE) -> 0 | AA18: =VLOOKUP(A18,Table4[#All],3,FALSE) -> 0 | AB18: =IFERROR(VLOOKUP(A18,Table13[[#Headers],[#Data]],7,FALSE),0) -> 0 | AC18: =SUM(Z18:AB18) -> 0 | AD18: =Z18*C18 -> 0 | AE18: =AA18*C18*1.5 -> 0 | AF18: =AB18*C18*2 -> 0 | AG18: =AD18+AE18+AF18 -> 0
A19: CASTRILLON, DERWIN ZABALA | B19: Electrician | C19: =VLOOKUP('1ST Shift'!$B19,Table6[],2,FALSE) -> 150 | L19: =(IF(E19>0,MIN(8,E19),"")) | M19: =IF((E19)>8,SUM(E19-L19),"") | N19: =(IF(F19>0,MIN(8,F19),"")) | O19: =IF((F19)>8,SUM(F19-N19),"") | P19: =(IF(G19>0,MIN(8,G19),"")) | Q19: =IF((G19)>8,SUM(G19-P19),"") | R19: =(IF(H19>0,MIN(8,H19),"")) | S19: =IF((H19)>8,SUM(H19-R19),"") | T19: =(IF(I19>0,MIN(8,I19),"")) | U19: =IF((I19)>8,SUM(I19-T19),"") | V19: =(IF(J19>0,MIN(8,J19),"")) | W19: =IF((J19)>8,SUM(J19-V19),"") | X19: =(IF(K19>0,MIN(8,K19),"")) | Y19: =IF((K19)>8,SUM(K19-X19),"") | Z19: =VLOOKUP(A19,Table4[#All],2,FALSE) -> 0 | AA19: =VLOOKUP(A19,Table4[#All],3,FALSE) -> 0 | AB19: =IFERROR(VLOOKUP(A19,Table13[[#Headers],[#Data]],7,FALSE),0) -> 0 | AC19: =SUM(Z19:AB19) -> 0 | AD19: =Z19*C19 -> 0 | AE19: =AA19*C19*1.5 -> 0 | AF19: =AB19*C19*2 -> 0 | AG19: =AD19+AE19+AF19 -> 0
A20: CHAVEZ, RICARDO | B20: Electrician | C20: =VLOOKUP('1ST Shift'!$B20,Table6[],2,FALSE) -> 150 | L20: =(IF(E20>0,MIN(8,E20),"")) | M20: =IF((E20)>8,SUM(E20-L20),"") | N20: =(IF(F20>0,MIN(8,F20),"")) | O20: =IF((F20)>8,SUM(F20-N20),"") | P20: =(IF(G20>0,MIN(8,G20),"")) | Q20: =IF((G20)>8,SUM(G20-P20),"") | R20: =(IF(H20>0,MIN(8,H20),"")) | S20: =IF((H20)>8,SUM(H20-R20),"") | T20: =(IF(I20>0,MIN(8,I20),"")) | U20: =IF((I20)>8,SUM(I20-T20),"") | V20: =(IF(J20>0,MIN(8,J20),"")) | W20: =IF((J20)>8,SUM(J20-V20),"") | X20: =(IF(K20>0,MIN(8,K20),"")) | Y20: =IF((K20)>8,SUM(K20-X20),"") | Z20: =VLOOKUP(A20,Table4[#All],2,FALSE) -> 0 | AA20: =VLOOKUP(A20,Table4[#All],3,FALSE) -> 0 | AB20: =IFERROR(VLOOKUP(A20,Table13[[#Headers],[#Data]],7,FALSE),0) -> 0 | AC20: =SUM(Z20:AB20) -> 0 | AD20: =Z20*C20 -> 0 | AE20: =AA20*C20*1.5 -> 0 | AF20: =AB20*C20*2 -> 0 | AG20: =AD20+AE20+AF20 -> 0
A21: CHINCHILLA, FRANK ESTUARDO | B21: Electrician | C21: =VLOOKUP('1ST Shift'!$B21,Table6[],2,FALSE) -> 150 | L21: =(IF(E21>0,MIN(8,E21),"")) | M21: =IF((E21)>8,SUM(E21-L21),"") | N21: =(IF(F21>0,MIN(8,F21),"")) | O21: =IF((F21)>8,SUM(F21-N21),"") | P21: =(IF(G21>0,MIN(8,G21),"")) | Q21: =IF((G21)>8,SUM(G21-P21),"") | R21: =(IF(H21>0,MIN(8,H21),"")) | S21: =IF((H21)>8,SUM(H21-R21),"") | T21: =(IF(I21>0,MIN(8,I21),"")) | U21: =IF((I21)>8,SUM(I21-T21),"") | V21: =(IF(J21>0,MIN(8,J21),"")) | W21: =IF((J21)>8,SUM(J21-V21),"") | X21: =(IF(K21>0,MIN(8,K21),"")) | Y21: =IF((K21)>8,SUM(K21-X21),"") | Z21: =VLOOKUP(A21,Table4[#All],2,FALSE) -> 0 | AA21: =VLOOKUP(A21,Table4[#All],3,FALSE) -> 0 | AB21: =IFERROR(VLOOKUP(A21,Table13[[#Headers],[#Data]],7,FALSE),0) -> 0 | AC21: =SUM(Z21:AB21) -> 0 | AD21: =Z21*C21 -> 0 | AE21: =AA21*C21*1.5 -> 0 | AF21: =AB21*C21*2 -> 0 | AG21: =AD21+AE21+AF21 -> 0
A22: COLON, CHRISTIAN RODRIGUEZ | B22: Electrician | C22: =VLOOKUP('1ST Shift'!$B22,Table6[],2,FALSE) -> 150 | L22: =(IF(E22>0,MIN(8,E22),"")) | M22: =IF((E22)>8,SUM(E22-L22),"") | N22: =(IF(F22>0,MIN(8,F22),"")) | O22: =IF((F22)>8,SUM(F22-N22),"") | P22: =(IF(G22>0,MIN(8,G22),"")) | Q22: =IF((G22)>8,SUM(G22-P22),"") | R22: =(IF(H22>0,MIN(8,H22),"")) | S22: =IF((H22)>8,SUM(H22-R22),"") | T22: =(IF(I22>0,MIN(8,I22),"")) | U22: =IF((I22)>8,SUM(I22-T22),"") | V22: =(IF(J22>0,MIN(8,J22),"")) | W22: =IF((J22)>8,SUM(J22-V22),"") | X22: =(IF(K22>0,MIN(8,K22),"")) | Y22: =IF((K22)>8,SUM(K22-X22),"") | Z22: =VLOOKUP(A22,Table4[#All],2,FALSE) -> 0 | AA22: =VLOOKUP(A22,Table4[#All],3,FALSE) -> 0 | AB22: =IFERROR(VLOOKUP(A22,Table13[[#Headers],[#Data]],7,FALSE),0) -> 0 | AC22: =SUM(Z22:AB22) -> 0 | AD22: =Z22*C22 -> 0 | AE22: =AA22*C22*1.5 -> 0 | AF22: =AB22*C22*2 -> 0 | AG22: =AD22+AE22+AF22 -> 0
A23: CONCHA, RAFAEL | B23: Electrician | C23: =VLOOKUP('1ST Shift'!$B23,Table6[],2,FALSE) -> 150 | L23: =(IF(E23>0,MIN(8,E23),"")) | M23: =IF((E23)>8,SUM(E23-L23),"") | N23: =(IF(F23>0,MIN(8,F23),"")) | O23: =IF((F23)>8,SUM(F23-N23),"") | P23: =(IF(G23>0,MIN(8,G23),"")) | Q23: =IF((G23)>8,SUM(G23-P23),"") | R23: =(IF(H23>0,MIN(8,H23),"")) | S23: =IF((H23)>8,SUM(H23-R23),"") | T23: =(IF(I23>0,MIN(8,I23),"")) | U23: =IF((I23)>8,SUM(I23-T23),"") | V23: =(IF(J23>0,MIN(8,J23),"")) | W23: =IF((J23)>8,SUM(J23-V23),"") | X23: =(IF(K23>0,MIN(8,K23),"")) | Y23: =IF((K23)>8,SUM(K23-X23),"") | Z23: =VLOOKUP(A23,Table4[#All],2,FALSE) -> 0 | AA23: =VLOOKUP(A23,Table4[#All],3,FALSE) -> 0 | AB23: =IFERROR(VLOOKUP(A23,Table13[[#Headers],[#Data]],7,FALSE),0) -> 0 | AC23: =SUM(Z23:AB23) -> 0 | AD23: =Z23*C23 -> 0 | AE23: =AA23*C23*1.5 -> 0 | AF23: =AB23*C23*2 -> 0 | AG23: =AD23+AE23+AF23 -> 0
A24: CONCHA, RUBEN | B24: QA/QC | C24: =VLOOKUP('1ST Shift'!$B24,Table6[],2,FALSE) -> 165 | L24: =(IF(E24>0,MIN(8,E24),"")) | M24: =IF((E24)>8,SUM(E24-L24),"") | N24: =(IF(F24>0,MIN(8,F24),"")) | O24: =IF((F24)>8,SUM(F24-N24),"") | P24: =(IF(G24>0,MIN(8,G24),"")) | Q24: =IF((G24)>8,SUM(G24-P24),"") | R24: =(IF(H24>0,MIN(8,H24),"")) | S24: =IF((H24)>8,SUM(H24-R24),"") | T24: =(IF(I24>0,MIN(8,I24),"")) | U24: =IF((I24)>8,SUM(I24-T24),"") | V24: =(IF(J24>0,MIN(8,J24),"")) | W24: =IF((J24)>8,SUM(J24-V24),"") | X24: =(IF(K24>0,MIN(8,K24),"")) | Y24: =IF((K24)>8,SUM(K24-X24),"") | Z24: =VLOOKUP(A24,Table4[#All],2,FALSE) -> 0 | AA24: =VLOOKUP(A24,Table4[#All],3,FALSE) -> 0 | AB24: =IFERROR(VLOOKUP(A24,Table13[[#Headers],[#Data]],7,FALSE),0) -> 0 | AC24: =SUM(Z24:AB24) -> 0 | AD24: =Z24*C24 -> 0 | AE24: =AA24*C24*1.5 -> 0 | AF24: =AB24*C24*2 -> 0 | AG24: =AD24+AE24+AF24 -> 0
A25: DE PALACIOS, JOSEFINA MOSCARELLA | B25: Electrician | C25: =VLOOKUP('1ST Shift'!$B25,Table6[],2,FALSE) -> 150 | L25: =(IF(E25>0,MIN(8,E25),"")) | M25: =IF((E25)>8,SUM(E25-L25),"") | N25: =(IF(F25>0,MIN(8,F25),"")) | O25: =IF((F25)>8,SUM(F25-N25),"") | P25: =(IF(G25>0,MIN(8,G25),"")) | Q25: =IF((G25)>8,SUM(G25-P25),"") | R25: =(IF(H25>0,MIN(8,H25),"")) | S25: =IF((H25)>8,SUM(H25-R25),"") | T25: =(IF(I25>0,MIN(8,I25),"")) | U25: =IF((I25)>8,SUM(I25-T25),"") | V25: =(IF(J25>0,MIN(8,J25),"")) | W25: =IF((J25)>8,SUM(J25-V25),"") | X25: =(IF(K25>0,MIN(8,K25),"")) | Y25: =IF((K25)>8,SUM(K25-X25),"") | Z25: =VLOOKUP(A25,Table4[#All],2,FALSE) -> 0 | AA25: =VLOOKUP(A25,Table4[#All],3,FALSE) -> 0 | AB25: =IFERROR(VLOOKUP(A25,Table13[[#Headers],[#Data]],7,FALSE),0) -> 0 | AC25: =SUM(Z25:AB25) -> 0 | AD25: =Z25*C25 -> 0 | AE25: =AA25*C25*1.5 -> 0 | AF25: =AB25*C25*2 -> 0 | AG25: =AD25+AE25+AF25 -> 0
A26: FERNANDEZ, JHON KENNETH HOWARD | B26: Electrician | C26: =VLOOKUP('1ST Shift'!$B26,Table6[],2,FALSE) -> 150 | L26: =(IF(E26>0,MIN(8,E26),"")) | M26: =IF((E26)>8,SUM(E26-L26),"") | N26: =(IF(F26>0,MIN(8,F26),"")) | O26: =IF((F26)>8,SUM(F26-N26),"") | P26: =(IF(G26>0,MIN(8,G26),"")) | Q26: =IF((G26)>8,SUM(G26-P26),"") | R26: =(IF(H26>0,MIN(8,H26),"")) | S26: =IF((H26)>8,SUM(H26-R26),"") | T26: =(IF(I26>0,MIN(8,I26),"")) | U26: =IF((I26)>8,SUM(I26-T26),"") | V26: =(IF(J26>0,MIN(8,J26),"")) | W26: =IF((J26)>8,SUM(J26-V26),"") | X26: =(IF(K26>0,MIN(8,K26),"")) | Y26: =IF((K26)>8,SUM(K26-X26),"") | Z26: =VLOOKUP(A26,Table4[#All],2,FALSE) -> 0 | AA26: =VLOOKUP(A26,Table4[#All],3,FALSE) -> 0 | AB26: =IFERROR(VLOOKUP(A26,Table13[[#Headers],[#Data]],7,FALSE),0) -> 0 | AC26: =SUM(Z26:AB26) -> 0 | AD26: =Z26*C26 -> 0 | AE26: =AA26*C26*1.5 -> 0 | AF26: =AB26*C26*2 -> 0 | AG26: =AD26+AE26+AF26 -> 0
... A32: GONZALEZ, ELDER | B32: Electrician | C32: =VLOOKUP('1ST Shift'!$B32,Table6[],2,FALSE) -> 150 | L32: =(IF(E32>0,MIN(8,E32),"")) | M32: =IF((E32)>8,SUM(E32-L32),"") | N32: =(IF(F32>0,MIN(8,F32),"")) | O32: =IF((F32)>8,SUM(F32-N32),"") | P32: =(IF(G32>0,MIN(8,G32),"")) | Q32: =IF((G32)>8,SUM(G32-P32),"") | R32: =(IF(H32>0,MIN(8,H32),"")) | S32: =IF((H32)>8,SUM(H32-R32),"") | T32: =(IF(I32>0,MIN(8,I32),"")) | U32: =IF((I32)>8,SUM(I32-T32),"") | V32: =(IF(J32>0,MIN(8,J32),"")) | W32: =IF((J32)>8,SUM(J32-V32),"") | X32: =(IF(K32>0,MIN(8,K32),"")) | Y32: =IF((K32)>8,SUM(K32-X32),"") | Z32: =VLOOKUP(A32,Table4[#All],2,FALSE) -> 0 | AA32: =VLOOKUP(A32,Table4[#All],3,FALSE) -> 0 | AB32: =IFERROR(VLOOKUP(A32,Table13[[#Headers],[#Data]],7,FALSE),0) -> 0 | AC32: =SUM(Z32:AB32) -> 0 | AD32: =Z32*C32 -> 0 | AE32: =AA32*C32*1.5 -> 0 | AF32: =AB32*C32*2 -> 0 | AG32: =AD32+AE32+AF32 -> 0
A33: INSKEEP, KYAH | B33: Project Coordinator Offsite | C33: =VLOOKUP('1ST Shift'!$B33,Table6[],2,FALSE) -> 165 | L33: =(IF(E33>0,MIN(8,E33),"")) | M33: =IF((E33)>8,SUM(E33-L33),"") | N33: =(IF(F33>0,MIN(8,F33),"")) | O33: =IF((F33)>8,SUM(F33-N33),"") | P33: =(IF(G33>0,MIN(8,G33),"")) | Q33: =IF((G33)>8,SUM(G33-P33),"") | R33: =(IF(H33>0,MIN(8,H33),"")) | S33: =IF((H33)>8,SUM(H33-R33),"") | T33: =(IF(I33>0,MIN(8,I33),"")) | U33: =IF((I33)>8,SUM(I33-T33),"") | V33: =(IF(J33>0,MIN(8,J33),"")) | W33: =IF((J33)>8,SUM(J33-V33),"") | X33: =(IF(K33>0,MIN(8,K33),"")) | Y33: =IF((K33)>8,SUM(K33-X33),"") | Z33: 3 | AA33: =VLOOKUP(A33,Table4[#All],3,FALSE) -> 0 | AB33: =IFERROR(VLOOKUP(A33,Table13[[#Headers],[#Data]],7,FALSE),0) -> 0 | AC33: =SUM(Z33:AB33) -> 3 | AD33: =Z33*C33 -> 495 | AE33: =AA33*C33*1.5 -> 0 | AF33: =AB33*C33*2 -> 0 | AG33: =AD33+AE33+AF33 -> 495 | AL33: 4 | AM33: =AC33-AL33 -> -1
A34: KONSTADINIDIS, BILL | B34: QA/QC | C34: =VLOOKUP('1ST Shift'!$B34,Table6[],2,FALSE) -> 165 | L34: =(IF(E34>0,MIN(8,E34),"")) | M34: =IF((E34)>8,SUM(E34-L34),"") | N34: =(IF(F34>0,MIN(8,F34),"")) | O34: =IF((F34)>8,SUM(F34-N34),"") | P34: =(IF(G34>0,MIN(8,G34),"")) | Q34: =IF((G34)>8,SUM(G34-P34),"") | R34: =(IF(H34>0,MIN(8,H34),"")) | S34: =IF((H34)>8,SUM(H34-R34),"") | T34: =(IF(I34>0,MIN(8,I34),"")) | U34: =IF((I34)>8,SUM(I34-T34),"") | V34: =(IF(J34>0,MIN(8,J34),"")) | W34: =IF((J34)>8,SUM(J34-V34),"") | X34: =(IF(K34>0,MIN(8,K34),"")) | Y34: =IF((K34)>8,SUM(K34-X34),"") | Z34: =VLOOKUP(A34,Table4[#All],2,FALSE) -> 0 | AA34: =VLOOKUP(A34,Table4[#All],3,FALSE) -> 0 | AB34: =IFERROR(VLOOKUP(A34,Table13[[#Headers],[#Data]],7,FALSE),0) -> 0 | AC34: =SUM(Z34:AB34) -> 0 | AD34: =Z34*C34 -> 0 | AE34: =AA34*C34*1.5 -> 0 | AF34: =AB34*C34*2 -> 0 | AG34: =AD34+AE34+AF34 -> 0 | AH34: biweekly | AK34: 40 | AL34: 40 | AM34: =AC34-AL34 -> -40
A35: LA CRUZ, JAVIER | B35: Electrician | C35: =VLOOKUP('1ST Shift'!$B35,Table6[],2,FALSE) -> 150 | L35: =(IF(E35>0,MIN(8,E35),"")) | M35: =IF((E35)>8,SUM(E35-L35),"") | N35: =(IF(F35>0,MIN(8,F35),"")) | O35: =IF((F35)>8,SUM(F35-N35),"") | P35: =(IF(G35>0,MIN(8,G35),"")) | Q35: =IF((G35)>8,SUM(G35-P35),"") | R35: =(IF(H35>0,MIN(8,H35),"")) | S35: =IF((H35)>8,SUM(H35-R35),"") | T35: =(IF(I35>0,MIN(8,I35),"")) | U35: =IF((I35)>8,SUM(I35-T35),"") | V35: =(IF(J35>0,MIN(8,J35),"")) | W35: =IF((J35)>8,SUM(J35-V35),"") | X35: =(IF(K35>0,MIN(8,K35),"")) | Y35: =IF((K35)>8,SUM(K35-X35),"") | Z35: =VLOOKUP(A35,Table4[#All],2,FALSE) -> 0 | AA35: =VLOOKUP(A35,Table4[#All],3,FALSE) -> 0 | AB35: =IFERROR(VLOOKUP(A35,Table13[[#Headers],[#Data]],7,FALSE),0) -> 0 | AC35: =SUM(Z35:AB35) -> 0 | AD35: =Z35*C35 -> 0 | AE35: =AA35*C35*1.5 -> 0 | AF35: =AB35*C35*2 -> 0 | AG35: =AD35+AE35+AF35 -> 0
A36: LINO, KEVIN | B36: Electrician | C36: =VLOOKUP('1ST Shift'!$B36,Table6[],2,FALSE) -> 150 | L36: =(IF(E36>0,MIN(8,E36),"")) | M36: =IF((E36)>8,SUM(E36-L36),"") | N36: =(IF(F36>0,MIN(8,F36),"")) | O36: =IF((F36)>8,SUM(F36-N36),"") | P36: =(IF(G36>0,MIN(8,G36),"")) | Q36: =IF((G36)>8,SUM(G36-P36),"") | R36: =(IF(H36>0,MIN(8,H36),"")) | S36: =IF((H36)>8,SUM(H36-R36),"") | T36: =(IF(I36>0,MIN(8,I36),"")) | U36: =IF((I36)>8,SUM(I36-T36),"") | V36: =(IF(J36>0,MIN(8,J36),"")) | W36: =IF((J36)>8,SUM(J36-V36),"") | X36: =(IF(K36>0,MIN(8,K36),"")) | Y36: =IF((K36)>8,SUM(K36-X36),"") | Z36: =VLOOKUP(A36,Table4[#All],2,FALSE) -> 0 | AA36: =VLOOKUP(A36,Table4[#All],3,FALSE) -> 0 | AB36: =IFERROR(VLOOKUP(A36,Table13[[#Headers],[#Data]],7,FALSE),0) -> 0 | AC36: =SUM(Z36:AB36) -> 0 | AD36: =Z36*C36 -> 0 | AE36: =AA36*C36*1.5 -> 0 | AF36: =AB36*C36*2 -> 0 | AG36: =AD36+AE36+AF36 -> 0
A37: MAVAREZ, FABRICIO MOLERO | B37: Electrician | C37: =VLOOKUP('1ST Shift'!$B37,Table6[],2,FALSE) -> 150 | L37: =(IF(E37>0,MIN(8,E37),"")) | M37: =IF((E37)>8,SUM(E37-L37),"") | N37: =(IF(F37>0,MIN(8,F37),"")) | O37: =IF((F37)>8,SUM(F37-N37),"") | P37: =(IF(G37>0,MIN(8,G37),"")) | Q37: =IF((G37)>8,SUM(G37-P37),"") | R37: =(IF(H37>0,MIN(8,H37),"")) | S37: =IF((H37)>8,SUM(H37-R37),"") | T37: =(IF(I37>0,MIN(8,I37),"")) | U37: =IF((I37)>8,SUM(I37-T37),"") | V37: =(IF(J37>0,MIN(8,J37),"")) | W37: =IF((J37)>8,SUM(J37-V37),"") | X37: =(IF(K37>0,MIN(8,K37),"")) | Y37: =IF((K37)>8,SUM(K37-X37),"") | Z37: =VLOOKUP(A37,Table4[#All],2,FALSE) -> 0 | AA37: =VLOOKUP(A37,Table4[#All],3,FALSE) -> 0 | AB37: =IFERROR(VLOOKUP(A37,Table13[[#Headers],[#Data]],7,FALSE),0) -> 0 | AC37: =SUM(Z37:AB37) -> 0 | AD37: =Z37*C37 -> 0 | AE37: =AA37*C37*1.5 -> 0 | AF37: =AB37*C37*2 -> 0 | AG37: =AD37+AE37+AF37 -> 0
A38: TURNER, MIRANDA | B38: Project Coordinator Offsite | C38: =VLOOKUP('1ST Shift'!$B38,Table6[],2,FALSE) -> 165 | L38: =(IF(E38>0,MIN(8,E38),"")) | M38: =IF((E38)>8,SUM(E38-L38),"") | N38: =(IF(F38>0,MIN(8,F38),"")) | O38: =IF((F38)>8,SUM(F38-N38),"") | P38: =(IF(G38>0,MIN(8,G38),"")) | Q38: =IF((G38)>8,SUM(G38-P38),"") | R38: =(IF(H38>0,MIN(8,H38),"")) | S38: =IF((H38)>8,SUM(H38-R38),"") | T38: =(IF(I38>0,MIN(8,I38),"")) | U38: =IF((I38)>8,SUM(I38-T38),"") | V38: =(IF(J38>0,MIN(8,J38),"")) | W38: =IF((J38)>8,SUM(J38-V38),"") | X38: =(IF(K38>0,MIN(8,K38),"")) | Y38: =IF((K38)>8,SUM(K38-X38),"") | Z38: 5.25 | AB38: =IFERROR(VLOOKUP(A38,Table13[[#Headers],[#Data]],7,FALSE),0) -> 0 | AC38: =SUM(Z38:AB38) -> 5.25 | AD38: =Z38*C38 -> 866.25 | AE38: =AA38*C38*1.5 -> 0 | AF38: =AB38*C38*2 -> 0 | AG38: =AD38+AE38+AF38 -> 866.25
A39: MEREZ, JESUS PALOMINO | B39: Electrician | C39: =VLOOKUP('1ST Shift'!$B39,Table6[],2,FALSE) -> 150 | L39: =(IF(E39>0,MIN(8,E39),"")) | M39: =IF((E39)>8,SUM(E39-L39),"") | N39: =(IF(F39>0,MIN(8,F39),"")) | O39: =IF((F39)>8,SUM(F39-N39),"") | P39: =(IF(G39>0,MIN(8,G39),"")) | Q39: =IF((G39)>8,SUM(G39-P39),"") | R39: =(IF(H39>0,MIN(8,H39),"")) | S39: =IF((H39)>8,SUM(H39-R39),"") | T39: =(IF(I39>0,MIN(8,I39),"")) | U39: =IF((I39)>8,SUM(I39-T39),"") | V39: =(IF(J39>0,MIN(8,J39),"")) | W39: =IF((J39)>8,SUM(J39-V39),"") | X39: =(IF(K39>0,MIN(8,K39),"")) | Y39: =IF((K39)>8,SUM(K39-X39),"") | Z39: =VLOOKUP(A39,Table4[#All],2,FALSE) -> 0 | AA39: =VLOOKUP(A39,Table4[#All],3,FALSE) -> 0 | AB39: =IFERROR(VLOOKUP(A39,Table13[[#Headers],[#Data]],7,FALSE),0) -> 0 | AC39: =SUM(Z39:AB39) -> 0 | AD39: =Z39*C39 -> 0 | AE39: =AA39*C39*1.5 -> 0 | AF39: =AB39*C39*2 -> 0 | AG39: =AD39+AE39+AF39 -> 0
A40: MEREDITH, ELISA | B40: Project Coordinator Offsite | C40: =VLOOKUP('1ST Shift'!$B40,Table6[],2,FALSE) -> 165 | L40: =(IF(E40>0,MIN(8,E40),"")) | M40: =IF((E40)>8,SUM(E40-L40),"") | N40: =(IF(F40>0,MIN(8,F40),"")) | O40: =IF((F40)>8,SUM(F40-N40),"") | P40: =(IF(G40>0,MIN(8,G40),"")) | Q40: =IF((G40)>8,SUM(G40-P40),"") | R40: =(IF(H40>0,MIN(8,H40),"")) | S40: =IF((H40)>8,SUM(H40-R40),"") | T40: =(IF(I40>0,MIN(8,I40),"")) | U40: =IF((I40)>8,SUM(I40-T40),"") | V40: =(IF(J40>0,MIN(8,J40),"")) | W40: =IF((J40)>8,SUM(J40-V40),"") | X40: =(IF(K40>0,MIN(8,K40),"")) | Y40: =IF((K40)>8,SUM(K40-X40),"") | Z40: 2 | AA40: =VLOOKUP(A40,Table4[#All],3,FALSE) -> 0 | AB40: =IFERROR(VLOOKUP(A40,Table13[[#Headers],[#Data]],7,FALSE),0) -> 0 | AC40: =SUM(Z40:AB40) -> 2 | AD40: =Z40*C40 -> 330 | AE40: =AA40*C40*1.5 -> 0 | AF40: =AB40*C40*2 -> 0 | AG40: =AD40+AE40+AF40 -> 330
A41: MUBIN, NASIR | B41: QA/QC Director | C41: =VLOOKUP('1ST Shift'!$B41,Table6[],2,FALSE) -> 175 | L41: =(IF(E41>0,MIN(8,E41),"")) | M41: =IF((E41)>8,SUM(E41-L41),"") | N41: =(IF(F41>0,MIN(8,F41),"")) | O41: =IF((F41)>8,SUM(F41-N41),"") | P41: =(IF(G41>0,MIN(8,G41),"")) | Q41: =IF((G41)>8,SUM(G41-P41),"") | R41: =(IF(H41>0,MIN(8,H41),"")) | S41: =IF((H41)>8,SUM(H41-R41),"") | T41: =(IF(I41>0,MIN(8,I41),"")) | U41: =IF((I41)>8,SUM(I41-T41),"") | V41: =(IF(J41>0,MIN(8,J41),"")) | W41: =IF((J41)>8,SUM(J41-V41),"") | X41: =(IF(K41>0,MIN(8,K41),"")) | Y41: =IF((K41)>8,SUM(K41-X41),"") | Z41: =VLOOKUP(A41,Table4[#All],2,FALSE) -> 0 | AA41: =VLOOKUP(A41,Table4[#All],3,FALSE) -> 0 | AB41: =IFERROR(VLOOKUP(A41,Table13[[#Headers],[#Data]],7,FALSE),0) -> 0 | AC41: =SUM(Z41:AB41) -> 0 | AD41: =Z41*C41 -> 0 | AE41: =AA41*C41*1.5 -> 0 | AF41: =AB41*C41*2 -> 0 | AG41: =AD41+AE41+AF41 -> 0
A42: ORDONES, MATHEUS | B42: Electrician | C42: =VLOOKUP('1ST Shift'!$B42,Table6[],2,FALSE) -> 150 | L42: =(IF(E42>0,MIN(8,E42),"")) | M42: =IF((E42)>8,SUM(E42-L42),"") | N42: =(IF(F42>0,MIN(8,F42),"")) | O42: =IF((F42)>8,SUM(F42-N42),"") | P42: =(IF(G42>0,MIN(8,G42),"")) | Q42: =IF((G42)>8,SUM(G42-P42),"") | R42: =(IF(H42>0,MIN(8,H42),"")) | S42: =IF((H42)>8,SUM(H42-R42),"") | T42: =(IF(I42>0,MIN(8,I42),"")) | U42: =IF((I42)>8,SUM(I42-T42),"") | V42: =(IF(J42>0,MIN(8,J42),"")) | W42: =IF((J42)>8,SUM(J42-V42),"") | X42: =(IF(K42>0,MIN(8,K42),"")) | Y42: =IF((K42)>8,SUM(K42-X42),"") | Z42: =VLOOKUP(A42,Table4[#All],2,FALSE) -> 0 | AA42: =VLOOKUP(A42,Table4[#All],3,FALSE) -> 0 | AB42: =IFERROR(VLOOKUP(A42,Table13[[#Headers],[#Data]],7,FALSE),0) -> 0 | AC42: =SUM(Z42:AB42) -> 0 | AD42: =Z42*C42 -> 0 | AE42: =AA42*C42*1.5 -> 0 | AF42: =AB42*C42*2 -> 0 | AG42: =AD42+AE42+AF42 -> 0
A43: OSORIO, JUAN BENCARDINO | B43: Electrician | C43: =VLOOKUP('1ST Shift'!$B43,Table6[],2,FALSE) -> 150 | L43: =(IF(E43>0,MIN(8,E43),"")) | M43: =IF((E43)>8,SUM(E43-L43),"") | N43: =(IF(F43>0,MIN(8,F43),"")) | O43: =IF((F43)>8,SUM(F43-N43),"") | P43: =(IF(G43>0,MIN(8,G43),"")) | Q43: =IF((G43)>8,SUM(G43-P43),"") | R43: =(IF(H43>0,MIN(8,H43),"")) | S43: =IF((H43)>8,SUM(H43-R43),"") | T43: =(IF(I43>0,MIN(8,I43),"")) | U43: =IF((I43)>8,SUM(I43-T43),"") | V43: =(IF(J43>0,MIN(8,J43),"")) | W43: =IF((J43)>8,SUM(J43-V43),"") | X43: =(IF(K43>0,MIN(8,K43),"")) | Y43: =IF((K43)>8,SUM(K43-X43),"") | Z43: =VLOOKUP(A43,Table4[#All],2,FALSE) -> 0 | AA43: =VLOOKUP(A43,Table4[#All],3,FALSE) -> 0 | AB43: =IFERROR(VLOOKUP(A43,Table13[[#Headers],[#Data]],7,FALSE),0) -> 0 | AC43: =SUM(Z43:AB43) -> 0 | AD43: =Z43*C43 -> 0 | AE43: =AA43*C43*1.5 -> 0 | AF43: =AB43*C43*2 -> 0 | AG43: =AD43+AE43+AF43 -> 0
A44: PALMAR, LUIS A. LABARCA | B44: Electrician | C44: =VLOOKUP('1ST Shift'!$B44,Table6[],2,FALSE) -> 150 | L44: =(IF(E44>0,MIN(8,E44),"")) | M44: =IF((E44)>8,SUM(E44-L44),"") | N44: =(IF(F44>0,MIN(8,F44),"")) | O44: =IF((F44)>8,SUM(F44-N44),"") | P44: =(IF(G44>0,MIN(8,G44),"")) | Q44: =IF((G44)>8,SUM(G44-P44),"") | R44: =(IF(H44>0,MIN(8,H44),"")) | S44: =IF((H44)>8,SUM(H44-R44),"") | T44: =(IF(I44>0,MIN(8,I44),"")) | U44: =IF((I44)>8,SUM(I44-T44),"") | V44: =(IF(J44>0,MIN(8,J44),"")) | W44: =IF((J44)>8,SUM(J44-V44),"") | X44: =(IF(K44>0,MIN(8,K44),"")) | Y44: =IF((K44)>8,SUM(K44-X44),"") | Z44: =VLOOKUP(A44,Table4[#All],2,FALSE) -> 0 | AA44: =VLOOKUP(A44,Table4[#All],3,FALSE) -> 0 | AB44: =IFERROR(VLOOKUP(A44,Table13[[#Headers],[#Data]],7,FALSE),0) -> 0 | AC44: =SUM(Z44:AB44) -> 0 | AD44: =Z44*C44 -> 0 | AE44: =AA44*C44*1.5 -> 0 | AF44: =AB44*C44*2 -> 0 | AG44: =AD44+AE44+AF44 -> 0
A45: PERDOMO, FELIX OMAR SEPULVEDA | B45: Electrician | C45: =VLOOKUP('1ST Shift'!$B45,Table6[],2,FALSE) -> 150 | L45: =(IF(E45>0,MIN(8,E45),"")) | M45: =IF((E45)>8,SUM(E45-L45),"") | N45: =(IF(F45>0,MIN(8,F45),"")) | O45: =IF((F45)>8,SUM(F45-N45),"") | P45: =(IF(G45>0,MIN(8,G45),"")) | Q45: =IF((G45)>8,SUM(G45-P45),"") | R45: =(IF(H45>0,MIN(8,H45),"")) | S45: =IF((H45)>8,SUM(H45-R45),"") | T45: =(IF(I45>0,MIN(8,I45),"")) | U45: =IF((I45)>8,SUM(I45-T45),"") | V45: =(IF(J45>0,MIN(8,J45),"")) | W45: =IF((J45)>8,SUM(J45-V45),"") | X45: =(IF(K45>0,MIN(8,K45),"")) | Y45: =IF((K45)>8,SUM(K45-X45),"") | Z45: =VLOOKUP(A45,Table4[#All],2,FALSE) -> 0 | AA45: =VLOOKUP(A45,Table4[#All],3,FALSE) -> 0 | AB45: =IFERROR(VLOOKUP(A45,Table13[[#Headers],[#Data]],7,FALSE),0) -> 0 | AC45: =SUM(Z45:AB45) -> 0 | AD45: =Z45*C45 -> 0 | AE45: =AA45*C45*1.5 -> 0 | AF45: =AB45*C45*2 -> 0 | AG45: =AD45+AE45+AF45 -> 0
A46: PEREIRA, MIGUEL | B46: Electrician | C46: =VLOOKUP('1ST Shift'!$B46,Table6[],2,FALSE) -> 150 | L46: =(IF(E46>0,MIN(8,E46),"")) | M46: =IF((E46)>8,SUM(E46-L46),"") | N46: =(IF(F46>0,MIN(8,F46),"")) | O46: =IF((F46)>8,SUM(F46-N46),"") | P46: =(IF(G46>0,MIN(8,G46),"")) | Q46: =IF((G46)>8,SUM(G46-P46),"") | R46: =(IF(H46>0,MIN(8,H46),"")) | S46: =IF((H46)>8,SUM(H46-R46),"") | T46: =(IF(I46>0,MIN(8,I46),"")) | U46: =IF((I46)>8,SUM(I46-T46),"") | V46: =(IF(J46>0,MIN(8,J46),"")) | W46: =IF((J46)>8,SUM(J46-V46),"") | X46: =(IF(K46>0,MIN(8,K46),"")) | Y46: =IF((K46)>8,SUM(K46-X46),"") | Z46: =VLOOKUP(A46,Table4[#All],2,FALSE) -> 0 | AA46: =VLOOKUP(A46,Table4[#All],3,FALSE) -> 0 | AB46: =IFERROR(VLOOKUP(A46,Table13[[#Headers],[#Data]],7,FALSE),0) -> 0 | AC46: =SUM(Z46:AB46) -> 0 | AD46: =Z46*C46 -> 0 | AE46: =AA46*C46*1.5 -> 0 | AF46: =AB46*C46*2 -> 0 | AG46: =AD46+AE46+AF46 -> 0
...

Sheet 6001 1st
A1: 6001 Original ROM TM Labor 1st Shift | AO1: on 8.15.25 payroll previously billed | AP1: will hit 8.29.25 | AQ1: Should be on JCH
A2: INPWR INVOICE NUMBER | B2: ='INVOICE COVER 7256'!F3 -> 25108-09
A3: CUSTOMER REFERENCE | B3: ='INVOICE COVER 7256'!D5 -> 7256
A4: JOB NAME | B4: ='INVOICE COVER 7256'!C5 -> Marble NC
A5: JOB NUMBER | B5: ='INVOICE COVER 7256'!E5 -> 25108
A6: Period Ending Week-ending 8.10.25 Thru | B6: ='INVOICE COVER 7256'!F5 -> 45942
A7: EMPLOYEE NAME | B7: CLASS | C7: REGULAR | D7: Per Diem | E7: PER DAY | L7: =B6-6 -> 45936 | N7: =B6-5 -> 45937 | P7: =B6-4 -> 45938 | R7: =B6-3 -> 45939 | T7: =B6-2 -> 45940 | V7: =B6-1 -> 45941 | X7: =B6 -> 45942 | Z7: REG | AA7: OT | AB7: DT | AC7: Total | AD7: ST. LABOR | AE7: OT LABOR | AF7: DT LABOR | AG7: LABOR
C8: RATE | D8: Y/N | E8: =B6-6 -> 45936 | F8: =E8+1 -> 45937 | G8: =F8+1 -> 45938 | H8: =G8+1 -> 45939 | I8: =H8+1 -> 45940 | J8: =I8+1 -> 45941 | K8: =J8+1 -> 45942 | L8: REG. | M8: OT | N8: REG. | O8: OT | P8: REG | Q8: OT | R8: REG | S8: OT | T8: REG | U8: OT | V8: REG | W8: OT | X8: REG | Y8: OT | Z8: TOT | AA8: TOT | AB8: Hours | AC8: Hours | AD8: TOTAL | AE8: TOTAL | AF8: TOTAL | AG8: TOTAL
A9: MUBIN, NASIR | B9: QA/QC | C9: =VLOOKUP('6001 1st'!$B9,Table6[],2,FALSE) -> 165 | L9: =(IF(E9>0,MIN(8,E9),"")) | M9: =IF((E9)>8,SUM(E9-L9),"") | N9: =(IF(F9>0,MIN(8,F9),"")) | O9: =IF((F9)>8,SUM(F9-N9),"") | P9: =(IF(G9>0,MIN(8,G9),"")) | Q9: =IF((G9)>8,SUM(G9-P9),"") | R9: =(IF(H9>0,MIN(8,H9),"")) | S9: =IF((H9)>8,SUM(H9-R9),"") | T9: =(IF(I9>0,MIN(8,I9),"")) | U9: =IF((I9)>8,SUM(I9-T9),"") | V9: =(IF(J9>0,MIN(8,J9),"")) | W9: =IF((J9)>8,SUM(J9-V9),"") | X9: =(IF(K9>0,MIN(8,K9),"")) | Y9: =IF((K9)>8,SUM(K9-X9),"") | Z9: =VLOOKUP(A9,#REF!,5,FALSE) -> #REF! | AA9: =VLOOKUP(A9,#REF!,6,FALSE) -> #REF! | AC9: =SUM(Z9:AB9) -> #REF! | AD9: =Z9*C9 -> #REF! | AE9: =AA9*C9*1.5 -> #REF! | AF9: =AB9*C9*2 -> 0 | AG9: =AD9+AE9+AF9 -> #REF!
A10: ACERO, MAURICIO | B10: Electrician | C10: =VLOOKUP('6001 1st'!$B10,Table6[],2,FALSE) -> 150 | Z10: =VLOOKUP(A10,#REF!,5,FALSE) -> #REF! | AA10: =VLOOKUP(A10,#REF!,6,FALSE) -> #REF! | AB10: =IFERROR(VLOOKUP(A10,Table13[[#Headers],[#Data]],7,FALSE),0) -> 0 | AC10: =SUM(Z10:AB10) -> #REF! | AD10: =Z10*C10 -> #REF! | AE10: =AA10*C10*1.5 -> #REF! | AF10: =AB10*C10*2 -> 0 | AG10: =AD10+AE10+AF10 -> #REF!
A11: AGUERO, JONATHAN | B11: Electrician | C11: =VLOOKUP('6001 1st'!$B11,Table6[],2,FALSE) -> 150 | L11: =(IF(E11>0,MIN(8,E11),"")) | M11: =IF((E11)>8,SUM(E11-L11),"") | N11: =(IF(F11>0,MIN(8,F11),"")) | O11: =IF((F11)>8,SUM(F11-N11),"") | P11: =(IF(G11>0,MIN(8,G11),"")) | Q11: =IF((G11)>8,SUM(G11-P11),"") | R11: =(IF(H11>0,MIN(8,H11),"")) | S11: =IF((H11)>8,SUM(H11-R11),"") | T11: =(IF(I11>0,MIN(8,I11),"")) | U11: =IF((I11)>8,SUM(I11-T11),"") | V11: =(IF(J11>0,MIN(8,J11),"")) | W11: =IF((J11)>8,SUM(J11-V11),"") | X11: =(IF(K11>0,MIN(8,K11),"")) | Y11: =IF((K11)>8,SUM(K11-X11),"") | Z11: =VLOOKUP(A11,#REF!,5,FALSE) -> #REF! | AA11: =VLOOKUP(A11,#REF!,6,FALSE) -> #REF! | AB11: =IFERROR(VLOOKUP(A11,Table13[[#Headers],[#Data]],7,FALSE),0) -> 0 | AC11: =SUM(Z11:AB11) -> #REF! | AD11: =Z11*C11 -> #REF! | AE11: =AA11*C11*1.5 -> #REF! | AF11: =AB11*C11*2 -> 0 | AG11: =AD11+AE11+AF11 -> #REF!
A12: ASHCRAFT, JOHN | B12: Electrician | C12: =VLOOKUP('6001 1st'!$B12,Table6[],2,FALSE) -> 150 | D12: Y | L12: =(IF(E12>0,MIN(8,E12),"")) | M12: =IF((E12)>8,SUM(E12-L12),"") | N12: =(IF(F12>0,MIN(8,F12),"")) | O12: =IF((F12)>8,SUM(F12-N12),"") | P12: =(IF(G12>0,MIN(8,G12),"")) | Q12: =IF((G12)>8,SUM(G12-P12),"") | R12: =(IF(H12>0,MIN(8,H12),"")) | S12: =IF((H12)>8,SUM(H12-R12),"") | T12: =(IF(I12>0,MIN(8,I12),"")) | U12: =IF((I12)>8,SUM(I12-T12),"") | V12: =(IF(J12>0,MIN(8,J12),"")) | W12: =IF((J12)>8,SUM(J12-V12),"") | X12: =(IF(K12>0,MIN(8,K12),"")) | Y12: =IF((K12)>8,SUM(K12-X12),"") | Z12: =VLOOKUP(A12,#REF!,5,FALSE) -> #REF! | AA12: =VLOOKUP(A12,#REF!,6,FALSE) -> #REF! | AB12: =IFERROR(VLOOKUP(A12,Table13[[#Headers],[#Data]],7,FALSE),0) -> 0 | AC12: =SUM(Z12:AB12) -> #REF! | AD12: =Z12*C12 -> #REF! | AE12: =AA12*C12*1.5 -> #REF! | AF12: =AB12*C12*2 -> 0 | AG12: =AD12+AE12+AF12 -> #REF!
A13: ARROYO, JESUS MACIAS | B13: Electrician | C13: =VLOOKUP('6001 1st'!$B13,Table6[],2,FALSE) -> 150 | L13: =(IF(E13>0,MIN(8,E13),"")) | M13: =IF((E13)>8,SUM(E13-L13),"") | N13: =(IF(F13>0,MIN(8,F13),"")) | O13: =IF((F13)>8,SUM(F13-N13),"") | P13: =(IF(G13>0,MIN(8,G13),"")) | Q13: =IF((G13)>8,SUM(G13-P13),"") | R13: =(IF(H13>0,MIN(8,H13),"")) | S13: =IF((H13)>8,SUM(H13-R13),"") | T13: =(IF(I13>0,MIN(8,I13),"")) | U13: =IF((I13)>8,SUM(I13-T13),"") | V13: =(IF(J13>0,MIN(8,J13),"")) | W13: =IF((J13)>8,SUM(J13-V13),"") | X13: =(IF(K13>0,MIN(8,K13),"")) | Y13: =IF((K13)>8,SUM(K13-X13),"") | Z13: =VLOOKUP(A13,#REF!,5,FALSE) -> #REF! | AA13: =VLOOKUP(A13,#REF!,6,FALSE) -> #REF! | AB13: =IFERROR(VLOOKUP(A13,Table13[[#Headers],[#Data]],7,FALSE),0) -> 0 | AC13: =SUM(Z13:AB13) -> #REF! | AD13: =Z13*C13 -> #REF! | AE13: =AA13*C13*1.5 -> #REF! | AF13: =AB13*C13*2 -> 0 | AG13: =AD13+AE13+AF13 -> #REF!
A14: AVILEZ, IVAN OMAR CASTILLO | B14: Electrician | C14: =VLOOKUP('6001 1st'!$B14,Table6[],2,FALSE) -> 150 | L14: =(IF(E14>0,MIN(8,E14),"")) | M14: =IF((E14)>8,SUM(E14-L14),"") | N14: =(IF(F14>0,MIN(8,F14),"")) | O14: =IF((F14)>8,SUM(F14-N14),"") | P14: =(IF(G14>0,MIN(8,G14),"")) | Q14: =IF((G14)>8,SUM(G14-P14),"") | R14: =(IF(H14>0,MIN(8,H14),"")) | S14: =IF((H14)>8,SUM(H14-R14),"") | T14: =(IF(I14>0,MIN(8,I14),"")) | U14: =IF((I14)>8,SUM(I14-T14),"") | V14: =(IF(J14>0,MIN(8,J14),"")) | W14: =IF((J14)>8,SUM(J14-V14),"") | X14: =(IF(K14>0,MIN(8,K14),"")) | Y14: =IF((K14)>8,SUM(K14-X14),"") | Z14: =VLOOKUP(A14,#REF!,5,FALSE) -> #REF! | AA14: =VLOOKUP(A14,#REF!,6,FALSE) -> #REF! | AB14: =IFERROR(VLOOKUP(A14,Table13[[#Headers],[#Data]],7,FALSE),0) -> 0 | AC14: =SUM(Z14:AB14) -> #REF! | AD14: =Z14*C14 -> #REF! | AE14: =AA14*C14*1.5 -> #REF! | AF14: =AB14*C14*2 -> 0 | AG14: =AD14+AE14+AF14 -> #REF!
A15: BARRIOS, ANDRES | B15: Electrician | C15: =VLOOKUP('6001 1st'!$B15,Table6[],2,FALSE) -> 150 | L15: =(IF(E15>0,MIN(8,E15),"")) | M15: =IF((E15)>8,SUM(E15-L15),"") | N15: =(IF(F15>0,MIN(8,F15),"")) | O15: =IF((F15)>8,SUM(F15-N15),"") | P15: =(IF(G15>0,MIN(8,G15),"")) | Q15: =IF((G15)>8,SUM(G15-P15),"") | R15: =(IF(H15>0,MIN(8,H15),"")) | S15: =IF((H15)>8,SUM(H15-R15),"") | T15: =(IF(I15>0,MIN(8,I15),"")) | U15: =IF((I15)>8,SUM(I15-T15),"") | V15: =(IF(J15>0,MIN(8,J15),"")) | W15: =IF((J15)>8,SUM(J15-V15),"") | X15: =(IF(K15>0,MIN(8,K15),"")) | Y15: =IF((K15)>8,SUM(K15-X15),"") | Z15: =VLOOKUP(A15,#REF!,5,FALSE) -> #REF! | AA15: =VLOOKUP(A15,#REF!,6,FALSE) -> #REF! | AB15: =IFERROR(VLOOKUP(A15,Table13[[#Headers],[#Data]],7,FALSE),0) -> 0 | AC15: =SUM(Z15:AB15) -> #REF! | AD15: =Z15*C15 -> #REF! | AE15: =AA15*C15*1.5 -> #REF! | AF15: =AB15*C15*2 -> 0 | AG15: =AD15+AE15+AF15 -> #REF!
A16: BAUTISTA, MELVIN HERNANDEZ | B16: Electrician | C16: =VLOOKUP('6001 1st'!$B16,Table6[],2,FALSE) -> 150 | L16: =(IF(E16>0,MIN(8,E16),"")) | M16: =IF((E16)>8,SUM(E16-L16),"") | N16: =(IF(F16>0,MIN(8,F16),"")) | O16: =IF((F16)>8,SUM(F16-N16),"") | P16: =(IF(G16>0,MIN(8,G16),"")) | Q16: =IF((G16)>8,SUM(G16-P16),"") | R16: =(IF(H16>0,MIN(8,H16),"")) | S16: =IF((H16)>8,SUM(H16-R16),"") | T16: =(IF(I16>0,MIN(8,I16),"")) | U16: =IF((I16)>8,SUM(I16-T16),"") | V16: =(IF(J16>0,MIN(8,J16),"")) | W16: =IF((J16)>8,SUM(J16-V16),"") | X16: =(IF(K16>0,MIN(8,K16),"")) | Y16: =IF((K16)>8,SUM(K16-X16),"") | Z16: =VLOOKUP(A16,#REF!,5,FALSE) -> #REF! | AA16: =VLOOKUP(A16,#REF!,6,FALSE) -> #REF! | AB16: =IFERROR(VLOOKUP(A16,Table13[[#Headers],[#Data]],7,FALSE),0) -> 0 | AC16: =SUM(Z16:AB16) -> #REF! | AD16: =Z16*C16 -> #REF! | AE16: =AA16*C16*1.5 -> #REF! | AF16: =AB16*C16*2 -> 0 | AG16: =AD16+AE16+AF16 -> #REF!
A17: BLANDON, ELVIN MORENO | B17: Electrician | C17: =VLOOKUP('6001 1st'!$B17,Table6[],2,FALSE) -> 150 | Z17: =VLOOKUP(A17,#REF!,5,FALSE) -> #REF! | AA17: =VLOOKUP(A17,#REF!,6,FALSE) -> #REF! | AB17: =IFERROR(VLOOKUP(A17,Table13[[#Headers],[#Data]],7,FALSE),0) -> 0 | AC17: =SUM(Z17:AB17) -> #REF! | AD17: =Z17*C17 -> #REF! | AE17: =AA17*C17*1.5 -> #REF! | AF17: =AB17*C17*2 -> 0 | AG17: =AD17+AE17+AF17 -> #REF!
A18: BLANDON, OSCAR DANILO MORENO | B18: Electrician | C18: =VLOOKUP('6001 1st'!$B18,Table6[],2,FALSE) -> 150 | Z18: =VLOOKUP(A18,#REF!,5,FALSE) -> #REF! | AA18: =VLOOKUP(A18,#REF!,6,FALSE) -> #REF! | AB18: =IFERROR(VLOOKUP(A18,Table13[[#Headers],[#Data]],7,FALSE),0) -> 0 | AC18: =SUM(Z18:AB18) -> #REF! | AD18: =Z18*C18 -> #REF! | AE18: =AA18*C18*1.5 -> #REF! | AF18: =AB18*C18*2 -> 0 | AG18: =AD18+AE18+AF18 -> #REF!
A19: BOHORQUEZ, AUDIE CHOURIO | B19: Electrician | C19: =VLOOKUP('6001 1st'!$B19,Table6[],2,FALSE) -> 150 | L19: =(IF(E19>0,MIN(8,E19),"")) | M19: =IF((E19)>8,SUM(E19-L19),"") | N19: =(IF(F19>0,MIN(8,F19),"")) | O19: =IF((F19)>8,SUM(F19-N19),"") | P19: =(IF(G19>0,MIN(8,G19),"")) | Q19: =IF((G19)>8,SUM(G19-P19),"") | R19: =(IF(H19>0,MIN(8,H19),"")) | S19: =IF((H19)>8,SUM(H19-R19),"") | T19: =(IF(I19>0,MIN(8,I19),"")) | U19: =IF((I19)>8,SUM(I19-T19),"") | V19: =(IF(J19>0,MIN(8,J19),"")) | W19: =IF((J19)>8,SUM(J19-V19),"") | X19: =(IF(K19>0,MIN(8,K19),"")) | Y19: =IF((K19)>8,SUM(K19-X19),"") | Z19: =VLOOKUP(A19,#REF!,5,FALSE) -> #REF! | AA19: =VLOOKUP(A19,#REF!,6,FALSE) -> #REF! | AB19: =IFERROR(VLOOKUP(A19,Table13[[#Headers],[#Data]],7,FALSE),0) -> 0 | AC19: =SUM(Z19:AB19) -> #REF! | AD19: =Z19*C19 -> #REF! | AE19: =AA19*C19*1.5 -> #REF! | AF19: =AB19*C19*2 -> 0 | AG19: =AD19+AE19+AF19 -> #REF!
A20: BRAVO, JOSE BRICERNO | B20: Electrician | C20: =VLOOKUP('6001 1st'!$B20,Table6[],2,FALSE) -> 150 | L20: =(IF(E20>0,MIN(8,E20),"")) | M20: =IF((E20)>8,SUM(E20-L20),"") | N20: =(IF(F20>0,MIN(8,F20),"")) | O20: =IF((F20)>8,SUM(F20-N20),"") | P20: =(IF(G20>0,MIN(8,G20),"")) | Q20: =IF((G20)>8,SUM(G20-P20),"") | R20: =(IF(H20>0,MIN(8,H20),"")) | S20: =IF((H20)>8,SUM(H20-R20),"") | T20: =(IF(I20>0,MIN(8,I20),"")) | U20: =IF((I20)>8,SUM(I20-T20),"") | V20: =(IF(J20>0,MIN(8,J20),"")) | W20: =IF((J20)>8,SUM(J20-V20),"") | X20: =(IF(K20>0,MIN(8,K20),"")) | Y20: =IF((K20)>8,SUM(K20-X20),"") | Z20: =VLOOKUP(A20,#REF!,5,FALSE) -> #REF! | AA20: =VLOOKUP(A20,#REF!,6,FALSE) -> #REF! | AB20: =IFERROR(VLOOKUP(A20,Table13[[#Headers],[#Data]],7,FALSE),0) -> 0 | AC20: =SUM(Z20:AB20) -> #REF! | AD20: =Z20*C20 -> #REF! | AE20: =AA20*C20*1.5 -> #REF! | AF20: =AB20*C20*2 -> 0 | AG20: =AD20+AE20+AF20 -> #REF!
A21: BUITRON, ROBERTO | B21: Electrician | C21: =VLOOKUP('6001 1st'!$B21,Table6[],2,FALSE) -> 150 | L21: =(IF(E21>0,MIN(8,E21),"")) | M21: =IF((E21)>8,SUM(E21-L21),"") | N21: =(IF(F21>0,MIN(8,F21),"")) | O21: =IF((F21)>8,SUM(F21-N21),"") | P21: =(IF(G21>0,MIN(8,G21),"")) | Q21: =IF((G21)>8,SUM(G21-P21),"") | R21: =(IF(H21>0,MIN(8,H21),"")) | S21: =IF((H21)>8,SUM(H21-R21),"") | T21: =(IF(I21>0,MIN(8,I21),"")) | U21: =IF((I21)>8,SUM(I21-T21),"") | V21: =(IF(J21>0,MIN(8,J21),"")) | W21: =IF((J21)>8,SUM(J21-V21),"") | X21: =(IF(K21>0,MIN(8,K21),"")) | Y21: =IF((K21)>8,SUM(K21-X21),"") | Z21: =VLOOKUP(A21,#REF!,5,FALSE) -> #REF! | AA21: =VLOOKUP(A21,#REF!,6,FALSE) -> #REF! | AB21: =IFERROR(VLOOKUP(A21,Table13[[#Headers],[#Data]],7,FALSE),0) -> 0 | AC21: =SUM(Z21:AB21) -> #REF! | AD21: =Z21*C21 -> #REF! | AE21: =AA21*C21*1.5 -> #REF! | AF21: =AB21*C21*2 -> 0 | AG21: =AD21+AE21+AF21 -> #REF!
A22: CAMPOS, JONATHAN RAMOS | B22: Electrician | C22: =VLOOKUP('6001 1st'!$B22,Table6[],2,FALSE) -> 150 | D22: Y | L22: =(IF(E22>0,MIN(8,E22),"")) | M22: =IF((E22)>8,SUM(E22-L22),"") | N22: =(IF(F22>0,MIN(8,F22),"")) | O22: =IF((F22)>8,SUM(F22-N22),"") | P22: =(IF(G22>0,MIN(8,G22),"")) | Q22: =IF((G22)>8,SUM(G22-P22),"") | R22: =(IF(H22>0,MIN(8,H22),"")) | S22: =IF((H22)>8,SUM(H22-R22),"") | T22: =(IF(I22>0,MIN(8,I22),"")) | U22: =IF((I22)>8,SUM(I22-T22),"") | V22: =(IF(J22>0,MIN(8,J22),"")) | W22: =IF((J22)>8,SUM(J22-V22),"") | X22: =(IF(K22>0,MIN(8,K22),"")) | Y22: =IF((K22)>8,SUM(K22-X22),"") | Z22: =VLOOKUP(A22,#REF!,5,FALSE) -> #REF! | AA22: =VLOOKUP(A22,#REF!,6,FALSE) -> #REF! | AB22: =IFERROR(VLOOKUP(A22,Table13[[#Headers],[#Data]],7,FALSE),0) -> 0 | AC22: =SUM(Z22:AB22) -> #REF! | AD22: =Z22*C22 -> #REF! | AE22: =AA22*C22*1.5 -> #REF! | AF22: =AB22*C22*2 -> 0 | AG22: =AD22+AE22+AF22 -> #REF!
A23: CARBALLO, DAVID | B23: Electrician | C23: =VLOOKUP('6001 1st'!$B23,Table6[],2,FALSE) -> 150 | L23: =(IF(E23>0,MIN(8,E23),"")) | M23: =IF((E23)>8,SUM(E23-L23),"") | N23: =(IF(F23>0,MIN(8,F23),"")) | O23: =IF((F23)>8,SUM(F23-N23),"") | P23: =(IF(G23>0,MIN(8,G23),"")) | Q23: =IF((G23)>8,SUM(G23-P23),"") | R23: =(IF(H23>0,MIN(8,H23),"")) | S23: =IF((H23)>8,SUM(H23-R23),"") | T23: =(IF(I23>0,MIN(8,I23),"")) | U23: =IF((I23)>8,SUM(I23-T23),"") | V23: =(IF(J23>0,MIN(8,J23),"")) | W23: =IF((J23)>8,SUM(J23-V23),"") | X23: =(IF(K23>0,MIN(8,K23),"")) | Y23: =IF((K23)>8,SUM(K23-X23),"") | Z23: =VLOOKUP(A23,#REF!,5,FALSE) -> #REF! | AA23: =VLOOKUP(A23,#REF!,6,FALSE) -> #REF! | AB23: =IFERROR(VLOOKUP(A23,Table13[[#Headers],[#Data]],7,FALSE),0) -> 0 | AC23: =SUM(Z23:AB23) -> #REF! | AD23: =Z23*C23 -> #REF! | AE23: =AA23*C23*1.5 -> #REF! | AF23: =AB23*C23*2 -> 0 | AG23: =AD23+AE23+AF23 -> #REF!
A24: CASANOVA, HUMBERTO FUENMAYOR | B24: Electrician | C24: =VLOOKUP('6001 1st'!$B24,Table6[],2,FALSE) -> 150 | L24: =(IF(E24>0,MIN(8,E24),"")) | M24: =IF((E24)>8,SUM(E24-L24),"") | N24: =(IF(F24>0,MIN(8,F24),"")) | O24: =IF((F24)>8,SUM(F24-N24),"") | P24: =(IF(G24>0,MIN(8,G24),"")) | Q24: =IF((G24)>8,SUM(G24-P24),"") | R24: =(IF(H24>0,MIN(8,H24),"")) | S24: =IF((H24)>8,SUM(H24-R24),"") | T24: =(IF(I24>0,MIN(8,I24),"")) | U24: =IF((I24)>8,SUM(I24-T24),"") | V24: =(IF(J24>0,MIN(8,J24),"")) | W24: =IF((J24)>8,SUM(J24-V24),"") | X24: =(IF(K24>0,MIN(8,K24),"")) | Y24: =IF((K24)>8,SUM(K24-X24),"") | Z24: =VLOOKUP(A24,#REF!,5,FALSE) -> #REF! | AA24: =VLOOKUP(A24,#REF!,6,FALSE) -> #REF! | AB24: =IFERROR(VLOOKUP(A24,Table13[[#Headers],[#Data]],7,FALSE),0) -> 0 | AC24: =SUM(Z24:AB24) -> #REF! | AD24: =Z24*C24 -> #REF! | AE24: =AA24*C24*1.5 -> #REF! | AF24: =AB24*C24*2 -> 0 | AG24: =AD24+AE24+AF24 -> #REF!
A25: CASTILLO, DERBYS URDANETA | B25: Electrician | C25: =VLOOKUP('6001 1st'!$B25,Table6[],2,FALSE) -> 150 | L25: =(IF(E25>0,MIN(8,E25),"")) | M25: =IF((E25)>8,SUM(E25-L25),"") | N25: =(IF(F25>0,MIN(8,F25),"")) | O25: =IF((F25)>8,SUM(F25-N25),"") | P25: =(IF(G25>0,MIN(8,G25),"")) | Q25: =IF((G25)>8,SUM(G25-P25),"") | R25: =(IF(H25>0,MIN(8,H25),"")) | S25: =IF((H25)>8,SUM(H25-R25),"") | T25: =(IF(I25>0,MIN(8,I25),"")) | U25: =IF((I25)>8,SUM(I25-T25),"") | V25: =(IF(J25>0,MIN(8,J25),"")) | W25: =IF((J25)>8,SUM(J25-V25),"") | X25: =(IF(K25>0,MIN(8,K25),"")) | Y25: =IF((K25)>8,SUM(K25-X25),"") | Z25: =VLOOKUP(A25,#REF!,5,FALSE) -> #REF! | AA25: =VLOOKUP(A25,#REF!,6,FALSE) -> #REF! | AB25: =IFERROR(VLOOKUP(A25,Table13[[#Headers],[#Data]],7,FALSE),0) -> 0 | AC25: =SUM(Z25:AB25) -> #REF! | AD25: =Z25*C25 -> #REF! | AE25: =AA25*C25*1.5 -> #REF! | AF25: =AB25*C25*2 -> 0 | AG25: =AD25+AE25+AF25 -> #REF!
A26: CASTILLO, JUAN SALAZAR DEL | B26: Electrician | C26: =VLOOKUP('6001 1st'!$B26,Table6[],2,FALSE) -> 150 | L26: =(IF(E26>0,MIN(8,E26),"")) | M26: =IF((E26)>8,SUM(E26-L26),"") | N26: =(IF(F26>0,MIN(8,F26),"")) | O26: =IF((F26)>8,SUM(F26-N26),"") | P26: =(IF(G26>0,MIN(8,G26),"")) | Q26: =IF((G26)>8,SUM(G26-P26),"") | R26: =(IF(H26>0,MIN(8,H26),"")) | S26: =IF((H26)>8,SUM(H26-R26),"") | T26: =(IF(I26>0,MIN(8,I26),"")) | U26: =IF((I26)>8,SUM(I26-T26),"") | V26: =(IF(J26>0,MIN(8,J26),"")) | W26: =IF((J26)>8,SUM(J26-V26),"") | X26: =(IF(K26>0,MIN(8,K26),"")) | Y26: =IF((K26)>8,SUM(K26-X26),"") | Z26: =VLOOKUP(A26,#REF!,5,FALSE) -> #REF! | AA26: =VLOOKUP(A26,#REF!,6,FALSE) -> #REF! | AB26: =IFERROR(VLOOKUP(A26,Table13[[#Headers],[#Data]],7,FALSE),0) -> 0 | AC26: =SUM(Z26:AB26) -> #REF! | AD26: =Z26*C26 -> #REF! | AE26: =AA26*C26*1.5 -> #REF! | AF26: =AB26*C26*2 -> 0 | AG26: =AD26+AE26+AF26 -> #REF!
A27: CASTILLO, LUIS YUNES | B27: Electrician | C27: =VLOOKUP('6001 1st'!$B27,Table6[],2,FALSE) -> 150 | L27: =(IF(E27>0,MIN(8,E27),"")) | M27: =IF((E27)>8,SUM(E27-L27),"") | N27: =(IF(F27>0,MIN(8,F27),"")) | O27: =IF((F27)>8,SUM(F27-N27),"") | P27: =(IF(G27>0,MIN(8,G27),"")) | Q27: =IF((G27)>8,SUM(G27-P27),"") | R27: =(IF(H27>0,MIN(8,H27),"")) | S27: =IF((H27)>8,SUM(H27-R27),"") | T27: =(IF(I27>0,MIN(8,I27),"")) | U27: =IF((I27)>8,SUM(I27-T27),"") | V27: =(IF(J27>0,MIN(8,J27),"")) | W27: =IF((J27)>8,SUM(J27-V27),"") | X27: =(IF(K27>0,MIN(8,K27),"")) | Y27: =IF((K27)>8,SUM(K27-X27),"") | Z27: =VLOOKUP(A27,#REF!,5,FALSE) -> #REF! | AA27: =VLOOKUP(A27,#REF!,6,FALSE) -> #REF! | AB27: =IFERROR(VLOOKUP(A27,Table13[[#Headers],[#Data]],7,FALSE),0) -> 0 | AC27: =SUM(Z27:AB27) -> #REF! | AD27: =Z27*C27 -> #REF! | AE27: =AA27*C27*1.5 -> #REF! | AF27: =AB27*C27*2 -> 0 | AG27: =AD27+AE27+AF27 -> #REF!
A28: CASTRILLON, DERWIN ZABALA | B28: Electrician | C28: =VLOOKUP('6001 1st'!$B28,Table6[],2,FALSE) -> 150 | L28: =(IF(E28>0,MIN(8,E28),"")) | M28: =IF((E28)>8,SUM(E28-L28),"") | N28: =(IF(F28>0,MIN(8,F28),"")) | O28: =IF((F28)>8,SUM(F28-N28),"") | P28: =(IF(G28>0,MIN(8,G28),"")) | Q28: =IF((G28)>8,SUM(G28-P28),"") | R28: =(IF(H28>0,MIN(8,H28),"")) | S28: =IF((H28)>8,SUM(H28-R28),"") | T28: =(IF(I28>0,MIN(8,I28),"")) | U28: =IF((I28)>8,SUM(I28-T28),"") | V28: =(IF(J28>0,MIN(8,J28),"")) | W28: =IF((J28)>8,SUM(J28-V28),"") | X28: =(IF(K28>0,MIN(8,K28),"")) | Y28: =IF((K28)>8,SUM(K28-X28),"") | Z28: =VLOOKUP(A28,#REF!,5,FALSE) -> #REF! | AA28: =VLOOKUP(A28,#REF!,6,FALSE) -> #REF! | AB28: =IFERROR(VLOOKUP(A28,Table13[[#Headers],[#Data]],7,FALSE),0) -> 0 | AC28: =SUM(Z28:AB28) -> #REF! | AD28: =Z28*C28 -> #REF! | AE28: =AA28*C28*1.5 -> #REF! | AF28: =AB28*C28*2 -> 0 | AG28: =AD28+AE28+AF28 -> #REF!
A29: CASTRO, DANIEL | B29: Electrician | C29: =VLOOKUP('6001 1st'!$B29,Table6[],2,FALSE) -> 150 | L29: =(IF(E29>0,MIN(8,E29),"")) | M29: =IF((E29)>8,SUM(E29-L29),"") | N29: =(IF(F29>0,MIN(8,F29),"")) | O29: =IF((F29)>8,SUM(F29-N29),"") | P29: =(IF(G29>0,MIN(8,G29),"")) | Q29: =IF((G29)>8,SUM(G29-P29),"") | R29: =(IF(H29>0,MIN(8,H29),"")) | S29: =IF((H29)>8,SUM(H29-R29),"") | T29: =(IF(I29>0,MIN(8,I29),"")) | U29: =IF((I29)>8,SUM(I29-T29),"") | V29: =(IF(J29>0,MIN(8,J29),"")) | W29: =IF((J29)>8,SUM(J29-V29),"") | X29: =(IF(K29>0,MIN(8,K29),"")) | Y29: =IF((K29)>8,SUM(K29-X29),"") | Z29: =VLOOKUP(A29,#REF!,5,FALSE) -> #REF! | AA29: =VLOOKUP(A29,#REF!,6,FALSE) -> #REF! | AB29: =IFERROR(VLOOKUP(A29,Table13[[#Headers],[#Data]],7,FALSE),0) -> 0 | AC29: =SUM(Z29:AB29) -> #REF! | AD29: =Z29*C29 -> #REF! | AE29: =AA29*C29*1.5 -> #REF! | AF29: =AB29*C29*2 -> 0 | AG29: =AD29+AE29+AF29 -> #REF!
A30: CHASE, SHANE | B30: Electrician | C30: =VLOOKUP('6001 1st'!$B30,Table6[],2,FALSE) -> 150 | L30: =(IF(E30>0,MIN(8,E30),"")) | M30: =IF((E30)>8,SUM(E30-L30),"") | N30: =(IF(F30>0,MIN(8,F30),"")) | O30: =IF((F30)>8,SUM(F30-N30),"") | P30: =(IF(G30>0,MIN(8,G30),"")) | Q30: =IF((G30)>8,SUM(G30-P30),"") | R30: =(IF(H30>0,MIN(8,H30),"")) | S30: =IF((H30)>8,SUM(H30-R30),"") | T30: =(IF(I30>0,MIN(8,I30),"")) | U30: =IF((I30)>8,SUM(I30-T30),"") | V30: =(IF(J30>0,MIN(8,J30),"")) | W30: =IF((J30)>8,SUM(J30-V30),"") | X30: =(IF(K30>0,MIN(8,K30),"")) | Y30: =IF((K30)>8,SUM(K30-X30),"") | Z30: =VLOOKUP(A30,#REF!,5,FALSE) -> #REF! | AA30: =VLOOKUP(A30,#REF!,6,FALSE) -> #REF! | AB30: =IFERROR(VLOOKUP(A30,Table13[[#Headers],[#Data]],7,FALSE),0) -> 0 | AC30: =SUM(Z30:AB30) -> #REF! | AD30: =Z30*C30 -> #REF! | AE30: =AA30*C30*1.5 -> #REF! | AF30: =AB30*C30*2 -> 0 | AG30: =AD30+AE30+AF30 -> #REF!
A31: CHAVARRIA, GLORIA CRISTINA TORREZ | B31: Electrician | C31: =VLOOKUP('6001 1st'!$B31,Table6[],2,FALSE) -> 150 | L31: =(IF(E31>0,MIN(8,E31),"")) | M31: =IF((E31)>8,SUM(E31-L31),"") | N31: =(IF(F31>0,MIN(8,F31),"")) | O31: =IF((F31)>8,SUM(F31-N31),"") | P31: =(IF(G31>0,MIN(8,G31),"")) | Q31: =IF((G31)>8,SUM(G31-P31),"") | R31: =(IF(H31>0,MIN(8,H31),"")) | S31: =IF((H31)>8,SUM(H31-R31),"") | T31: =(IF(I31>0,MIN(8,I31),"")) | U31: =IF((I31)>8,SUM(I31-T31),"") | V31: =(IF(J31>0,MIN(8,J31),"")) | W31: =IF((J31)>8,SUM(J31-V31),"") | X31: =(IF(K31>0,MIN(8,K31),"")) | Y31: =IF((K31)>8,SUM(K31-X31),"") | Z31: =VLOOKUP(A31,#REF!,5,FALSE) -> #REF! | AA31: =VLOOKUP(A31,#REF!,6,FALSE) -> #REF! | AB31: =IFERROR(VLOOKUP(A31,Table13[[#Headers],[#Data]],7,FALSE),0) -> 0 | AC31: =SUM(Z31:AB31) -> #REF! | AD31: =Z31*C31 -> #REF! | AE31: =AA31*C31*1.5 -> #REF! | AF31: =AB31*C31*2 -> 0 | AG31: =AD31+AE31+AF31 -> #REF!
